Workbook
Name R_: Checks!$A$69:$O$71
Name R_: E_Final_2000!$A$62:$M$64
Name R_: X_Final_2000!$A$68:$O$70
Name r_EIOU: Checks!$AD$2:$AO$16
Name r_EIOU: E_Final_2000!$AB$1:$AK$13
Name r_EIOU: X_Final_2000!$AD$1:$AM$15
Name S_units: Checks!$A$2:$B$16
Name S_units: E_Final_2000!$A$1:$B$13
Name S_units: X_Final_2000!$A$1:$B$15
Name U: Checks!$R$38:$AA$52
Name U: E_Final_2000!$P$33:$Y$45
Name U: X_Final_2000!$R$37:$AA$51
Name U_EIOU: Checks!$R$2:$AA$16
Name U_EIOU: E_Final_2000!$P$1:$Y$13
Name U_EIOU: X_Final_2000!$R$1:$AA$15
Name U_feed: Checks!$R$20:$AA$34
Name U_feed: E_Final_2000!$P$17:$Y$29
Name U_feed: X_Final_2000!$R$19:$AA$33
Name V: Checks!$A$56:$O$65
Name V: E_Final_2000!$A$49:$M$58
Name V: X_Final_2000!$A$55:$O$64
Name Y: Checks!$AD$38:$AF$52
Name Y: E_Final_2000!$AB$33:$AD$45
Name Y: X_Final_2000!$AD$37:$AH$51

Sheet E_Final_2000
B1: ktoe | Q1: Crude dist. | R1: Diesel dist. | S1: Elect. grid | T1: Gas wells & proc. | U1: NG dist. | V1: Oil fields | W1: Oil refineries | X1: Petrol dist. | Y1: Power plants | AC1: Crude dist. | AD1: Diesel dist. | AE1: Elect. grid | AF1: Gas wells & proc. | AG1: NG dist. | AH1: Oil fields | AI1: Oil refineries | AJ1: Petrol dist. | AK1: Power plants
A2: Crude | B2: 1 | P2: Crude | Q2: 0 | R2: 0 | S2: 0 | T2: 0 | U2: 0 | V2: 0 | W2: 0 | X2: 0 | Y2: 0 | AB2: Crude | AC2: 0 | AD2: 0 | AE2: 0 | AF2: 0 | AG2: 0 | AH2: 0 | AI2: 0 | AJ2: 0 | AK2: 0
A3: Crude [from Dist.] | B3: 1 | P3: Crude [from Dist.] | Q3: 500 | R3: 0 | S3: 0 | T3: 0 | U3: 0 | V3: 0 | W3: 0 | X3: 0 | Y3: 0 | AB3: Crude [from Dist.] | AC3: 1 | AD3: 0 | AE3: 0 | AF3: 0 | AG3: 0 | AH3: 0 | AI3: 0 | AJ3: 0 | AK3: 0
A4: Crude [from Fields] | B4: 1 | P4: Crude [from Fields] | Q4: 0 | R4: 0 | S4: 0 | T4: 0 | U4: 0 | V4: 2500 | W4: 0 | X4: 0 | Y4: 0 | AB4: Crude [from Fields] | AC4: 0 | AD4: 0 | AE4: 0 | AF4: 0 | AG4: 0 | AH4: 1 | AI4: 0 | AJ4: 0 | AK4: 0
A5: Diesel | B5: 1 | P5: Diesel | Q5: 0 | R5: 0 | S5: 0 | T5: 0 | U5: 0 | V5: 0 | W5: 5000 | X5: 0 | Y5: 0 | AB5: Diesel | AC5: 0 | AD5: 0 | AE5: 0 | AF5: 0 | AG5: 0 | AH5: 0 | AI5: 1 | AJ5: 0 | AK5: 0
A6: Diesel [from Dist.] | B6: 1 | P6: Diesel [from Dist.] | Q6: 25 | R6: 350 | S6: 0 | T6: 50 | U6: 25 | V6: 50 | W6: 0 | X6: 250 | Y6: 0 | AB6: Diesel [from Dist.] | AC6: 1 | AD6: 1 | AE6: 0 | AF6: 1 | AG6: 1 | AH6: 1 | AI6: 0 | AJ6: 1 | AK6: 0
A7: Elect | B7: 1 | P7: Elect | Q7: 0 | R7: 0 | S7: 0 | T7: 0 | U7: 0 | V7: 0 | W7: 0 | X7: 0 | Y7: 0 | AB7: Elect | AC7: 0 | AD7: 0 | AE7: 0 | AF7: 0 | AG7: 0 | AH7: 0 | AI7: 0 | AJ7: 0 | AK7: 0
A8: Elect [from Grid] | B8: 1 | P8: Elect [from Grid] | Q8: 25 | R8: 0 | S8: 0 | T8: 25 | U8: 25 | V8: 25 | W8: 75 | X8: 0 | Y8: 100 | AB8: Elect [from Grid] | AC8: 1 | AD8: 0 | AE8: 0 | AF8: 1 | AG8: 1 | AH8: 1 | AI8: 1 | AJ8: 0 | AK8: 1
A9: NG | B9: 1 | P9: NG | Q9: 0 | R9: 0 | S9: 0 | T9: 0 | U9: 0 | V9: 0 | W9: 0 | X9: 0 | Y9: 0 | AB9: NG | AC9: 0 | AD9: 0 | AE9: 0 | AF9: 0 | AG9: 0 | AH9: 0 | AI9: 0 | AJ9: 0 | AK9: 0
A10: NG [from Dist.] | B10: 1 | P10: NG [from Dist.] | Q10: 0 | R10: 0 | S10: 0 | T10: 0 | U10: 0 | V10: 0 | W10: 0 | X10: 0 | Y10: 0 | AB10: NG [from Dist.] | AC10: 0 | AD10: 0 | AE10: 0 | AF10: 0 | AG10: 0 | AH10: 0 | AI10: 0 | AJ10: 0 | AK10: 0
A11: NG [from Wells] | B11: 1 | P11: NG [from Wells] | Q11: 0 | R11: 0 | S11: 0 | T11: 2000 | U11: 0 | V11: 0 | W11: 0 | X11: 0 | Y11: 0 | AB11: NG [from Wells] | AC11: 0 | AD11: 0 | AE11: 0 | AF11: 1 | AG11: 0 | AH11: 0 | AI11: 0 | AJ11: 0 | AK11: 0
A12: Petrol | B12: 1 | P12: Petrol | Q12: 0 | R12: 0 | S12: 0 | T12: 0 | U12: 0 | V12: 0 | W12: 0 | X12: 0 | Y12: 0 | AB12: Petrol | AC12: 0 | AD12: 0 | AE12: 0 | AF12: 0 | AG12: 0 | AH12: 0 | AI12: 0 | AJ12: 0 | AK12: 0
A13: Petrol [from Dist.] | B13: 1 | P13: Petrol [from Dist.] | Q13: 0 | R13: 0 | S13: 0 | T13: 0 | U13: 0 | V13: 0 | W13: 0 | X13: 500 | Y13: 0 | AB13: Petrol [from Dist.] | AC13: 0 | AD13: 0 | AE13: 0 | AF13: 0 | AG13: 0 | AH13: 0 | AI13: 0 | AJ13: 1 | AK13: 0
B14: S_units | Q14: U_EIOU | AC14: r_EIOU
Q17: Crude dist. | R17: Diesel dist. | S17: Elect. grid | T17: Gas wells & proc. | U17: NG dist. | V17: Oil fields | W17: Oil refineries | X17: Petrol dist. | Y17: Power plants
P18: Crude | Q18: 0 | R18: 0 | S18: 0 | T18: 0 | U18: 0 | V18: 50000 | W18: 0 | X18: 0 | Y18: 0
P19: Crude [from Dist.] | Q19: 0 | R19: 0 | S19: 0 | T19: 0 | U19: 0 | V19: 0 | W19: 47000 | X19: 0 | Y19: 0
P20: Crude [from Fields] | Q20: 47500 | R20: 0 | S20: 0 | T20: 0 | U20: 0 | V20: 0 | W20: 0 | X20: 0 | Y20: 0
P21: Diesel | Q21: 0 | R21: 15500 | S21: 0 | T21: 0 | U21: 0 | V21: 0 | W21: 0 | X21: 0 | Y21: 0
P22: Diesel [from Dist.] | Q22: 0 | R22: 0 | S22: 0 | T22: 0 | U22: 0 | V22: 0 | W22: 0 | X22: 0 | Y22: 0
P23: Elect | Q23: 0 | R23: 0 | S23: 6400 | T23: 0 | U23: 0 | V23: 0 | W23: 0 | X23: 0 | Y23: 0
P24: Elect [from Grid] | Q24: 0 | R24: 0 | S24: 0 | T24: 0 | U24: 0 | V24: 0 | W24: 0 | X24: 0 | Y24: 0
P25: NG | Q25: 0 | R25: 0 | S25: 0 | T25: 43000 | U25: 0 | V25: 0 | W25: 0 | X25: 0 | Y25: 0
P26: NG [from Dist.] | Q26: 0 | R26: 0 | S26: 0 | T26: 0 | U26: 0 | V26: 0 | W26: 0 | X26: 0 | Y26: 16000
P27: NG [from Wells] | Q27: 0 | R27: 0 | S27: 0 | T27: 0 | U27: 41000 | V27: 0 | W27: 0 | X27: 0 | Y27: 0
P28: Petrol | Q28: 0 | R28: 0 | S28: 0 | T28: 0 | U28: 0 | V28: 0 | W28: 0 | X28: 26500 | Y28: 0
P29: Petrol [from Dist.] | Q29: 0 | R29: 0 | S29: 0 | T29: 0 | U29: 0 | V29: 0 | W29: 0 | X29: 0 | Y29: 0
Q30: U_feed
Q33: Crude dist. | R33: Diesel dist. | S33: Elect. grid | T33: Gas wells & proc. | U33: NG dist. | V33: Oil fields | W33: Oil refineries | X33: Petrol dist. | Y33: Power plants | AC33: Residential | AD33: Transport
P34: Crude | Q34: 0 | R34: 0 | S34: 0 | T34: 0 | U34: 0 | V34: 50000 | W34: 0 | X34: 0 | Y34: 0 | AB34: Crude | AC34: 0 | AD34: 0
P35: Crude [from Dist.] | Q35: 500 | R35: 0 | S35: 0 | T35: 0 | U35: 0 | V35: 0 | W35: 47000 | X35: 0 | Y35: 0 | AB35: Crude [from Dist.] | AC35: 0 | AD35: 0
P36: Crude [from Fields] | Q36: 47500 | R36: 0 | S36: 0 | T36: 0 | U36: 0 | V36: 2500 | W36: 0 | X36: 0 | Y36: 0 | AB36: Crude [from Fields] | AC36: 0 | AD36: 0
P37: Diesel | Q37: 0 | R37: 15500 | S37: 0 | T37: 0 | U37: 0 | V37: 0 | W37: 5000 | X37: 0 | Y37: 0 | AB37: Diesel | AC37: 0 | AD37: 0
P38: Diesel [from Dist.] | Q38: 25 | R38: 350 | S38: 0 | T38: 50 | U38: 25 | V38: 50 | W38: 0 | X38: 250 | Y38: 0 | AB38: Diesel [from Dist.] | AC38: 0 | AD38: 14750
P39: Elect | Q39: 0 | R39: 0 | S39: 6400 | T39: 0 | U39: 0 | V39: 0 | W39: 0 | X39: 0 | Y39: 0 | AB39: Elect | AC39: 0 | AD39: 0
P40: Elect [from Grid] | Q40: 25 | R40: 0 | S40: 0 | T40: 25 | U40: 25 | V40: 25 | W40: 75 | X40: 0 | Y40: 100 | AB40: Elect [from Grid] | AC40: 6000 | AD40: 0
P41: NG | Q41: 0 | R41: 0 | S41: 0 | T41: 43000 | U41: 0 | V41: 0 | W41: 0 | X41: 0 | Y41: 0 | AB41: NG | AC41: 0 | AD41: 0
P42: NG [from Dist.] | Q42: 0 | R42: 0 | S42: 0 | T42: 0 | U42: 0 | V42: 0 | W42: 0 | X42: 0 | Y42: 16000 | AB42: NG [from Dist.] | AC42: 25000 | AD42: 0
P43: NG [from Wells] | Q43: 0 | R43: 0 | S43: 0 | T43: 2000 | U43: 41000 | V43: 0 | W43: 0 | X43: 0 | Y43: 0 | AB43: NG [from Wells] | AC43: 0 | AD43: 0
P44: Petrol | Q44: 0 | R44: 0 | S44: 0 | T44: 0 | U44: 0 | V44: 0 | W44: 0 | X44: 26500 | Y44: 0 | AB44: Petrol | AC44: 0 | AD44: 0
...

Sheet X_Final_2000
B1: ktoe | S1: Crude dist. | T1: Diesel dist. | U1: Elect. grid | V1: Gas wells & proc. | W1: NG dist. | X1: Oil fields | Y1: Oil refineries | Z1: Petrol dist. | AA1: Power plants | AE1: Crude dist. | AF1: Diesel dist. | AG1: Elect. grid | AH1: Gas wells & proc. | AI1: NG dist. | AJ1: Oil fields | AK1: Oil refineries | AL1: Petrol dist. | AM1: Power plants
A2: Crude | B2: 1 | R2: Crude | S2: 0 | T2: 0 | U2: 0 | V2: 0 | W2: 0 | X2: 0 | Y2: 0 | Z2: 0 | AA2: 0 | AD2: Crude | AE2: 0 | AF2: 0 | AG2: 0 | AH2: 0 | AI2: 0 | AJ2: 0 | AK2: 0 | AL2: 0 | AM2: 0
A3: Crude [from Dist.] | B3: 1 | R3: Crude [from Dist.] | S3: 530 | T3: 0 | U3: 0 | V3: 0 | W3: 0 | X3: 0 | Y3: 0 | Z3: 0 | AA3: 0 | AD3: Crude [from Dist.] | AE3: 1 | AF3: 0 | AG3: 0 | AH3: 0 | AI3: 0 | AJ3: 0 | AK3: 0 | AL3: 0 | AM3: 0
A4: Crude [from Fields] | B4: 1 | R4: Crude [from Fields] | S4: 0 | T4: 0 | U4: 0 | V4: 0 | W4: 0 | X4: 2650 | Y4: 0 | Z4: 0 | AA4: 0 | AD4: Crude [from Fields] | AE4: 0 | AF4: 0 | AG4: 0 | AH4: 0 | AI4: 0 | AJ4: 1 | AK4: 0 | AL4: 0 | AM4: 0
A5: Destroyed exergy | B5: 0 | R5: Destroyed exergy | S5: 0 | T5: 0 | U5: 0 | V5: 0 | W5: 0 | X5: 0 | Y5: 0 | Z5: 0 | AA5: 0 | AD5: Destroyed exergy | AE5: 0 | AF5: 0 | AG5: 0 | AH5: 0 | AI5: 0 | AJ5: 0 | AK5: 0 | AL5: 0 | AM5: 0
A6: Diesel | B6: 1 | R6: Diesel | S6: 0 | T6: 0 | U6: 0 | V6: 0 | W6: 0 | X6: 0 | Y6: 5300 | Z6: 0 | AA6: 0 | AD6: Diesel | AE6: 0 | AF6: 0 | AG6: 0 | AH6: 0 | AI6: 0 | AJ6: 0 | AK6: 1 | AL6: 0 | AM6: 0
A7: Diesel [from Dist.] | B7: 1 | R7: Diesel [from Dist.] | S7: 26.5 | T7: 371 | U7: 0 | V7: 53 | W7: 26.5 | X7: 53 | Y7: 0 | Z7: 265 | AA7: 0 | AD7: Diesel [from Dist.] | AE7: 1 | AF7: 1 | AG7: 0 | AH7: 1 | AI7: 1 | AJ7: 1 | AK7: 0 | AL7: 1 | AM7: 0
A8: Elect | B8: 1 | R8: Elect | S8: 0 | T8: 0 | U8: 0 | V8: 0 | W8: 0 | X8: 0 | Y8: 0 | Z8: 0 | AA8: 0 | AD8: Elect | AE8: 0 | AF8: 0 | AG8: 0 | AH8: 0 | AI8: 0 | AJ8: 0 | AK8: 0 | AL8: 0 | AM8: 0
A9: Elect [from Grid] | B9: 1 | R9: Elect [from Grid] | S9: 25 | T9: 0 | U9: 0 | V9: 25 | W9: 25 | X9: 25 | Y9: 75 | Z9: 0 | AA9: 100 | AD9: Elect [from Grid] | AE9: 1 | AF9: 0 | AG9: 0 | AH9: 1 | AI9: 1 | AJ9: 1 | AK9: 1 | AL9: 0 | AM9: 1
A10: MTH.200.C -> Transformation losses | B10: 0 | R10: MTH.200.C -> Transformation losses | S10: 0 | T10: 0 | U10: 0 | V10: 0 | W10: 0 | X10: 0 | Y10: 0 | Z10: 0 | AA10: 0 | AD10: MTH.200.C -> Transformation losses | AE10: 0 | AF10: 0 | AG10: 0 | AH10: 0 | AI10: 0 | AJ10: 0 | AK10: 0 | AL10: 0 | AM10: 0
A11: NG | B11: 1 | R11: NG | S11: 0 | T11: 0 | U11: 0 | V11: 0 | W11: 0 | X11: 0 | Y11: 0 | Z11: 0 | AA11: 0 | AD11: NG | AE11: 0 | AF11: 0 | AG11: 0 | AH11: 0 | AI11: 0 | AJ11: 0 | AK11: 0 | AL11: 0 | AM11: 0
A12: NG [from Dist.] | B12: 1 | R12: NG [from Dist.] | S12: 0 | T12: 0 | U12: 0 | V12: 0 | W12: 0 | X12: 0 | Y12: 0 | Z12: 0 | AA12: 0 | AD12: NG [from Dist.] | AE12: 0 | AF12: 0 | AG12: 0 | AH12: 0 | AI12: 0 | AJ12: 0 | AK12: 0 | AL12: 0 | AM12: 0
A13: NG [from Wells] | B13: 1 | R13: NG [from Wells] | S13: 0 | T13: 0 | U13: 0 | V13: 2080 | W13: 0 | X13: 0 | Y13: 0 | Z13: 0 | AA13: 0 | AD13: NG [from Wells] | AE13: 0 | AF13: 0 | AG13: 0 | AH13: 1 | AI13: 0 | AJ13: 0 | AK13: 0 | AL13: 0 | AM13: 0
... A15: Petrol [from Dist.] | B15: 1 | R15: Petrol [from Dist.] | S15: 0 | T15: 0 | U15: 0 | V15: 0 | W15: 0 | X15: 0 | Y15: 0 | Z15: 530 | AA15: 0 | AD15: Petrol [from Dist.] | AE15: 0 | AF15: 0 | AG15: 0 | AH15: 0 | AI15: 0 | AJ15: 0 | AK15: 0 | AL15: 1 | AM15: 0
B16: S_units | S16: U_EIOU | AE16: r_EIOU
S19: Crude dist. | T19: Diesel dist. | U19: Elect. grid | V19: Gas wells & proc. | W19: NG dist. | X19: Oil fields | Y19: Oil refineries | Z19: Petrol dist. | AA19: Power plants
R20: Crude | S20: 0 | T20: 0 | U20: 0 | V20: 0 | W20: 0 | X20: 53000 | Y20: 0 | Z20: 0 | AA20: 0
R21: Crude [from Dist.] | S21: 0 | T21: 0 | U21: 0 | V21: 0 | W21: 0 | X21: 0 | Y21: 49820 | Z21: 0 | AA21: 0
R22: Crude [from Fields] | S22: 50350 | T22: 0 | U22: 0 | V22: 0 | W22: 0 | X22: 0 | Y22: 0 | Z22: 0 | AA22: 0
R23: Destroyed exergy | S23: 0 | T23: 0 | U23: 0 | V23: 0 | W23: 0 | X23: 0 | Y23: 0 | Z23: 0 | AA23: 0
R24: Diesel | S24: 0 | T24: 16430 | U24: 0 | V24: 0 | W24: 0 | X24: 0 | Y24: 0 | Z24: 0 | AA24: 0
R25: Diesel [from Dist.] | S25: 0 | T25: 0 | U25: 0 | V25: 0 | W25: 0 | X25: 0 | Y25: 0 | Z25: 0 | AA25: 0
R26: Elect | S26: 0 | T26: 0 | U26: 6400 | V26: 0 | W26: 0 | X26: 0 | Y26: 0 | Z26: 0 | AA26: 0
R27: Elect [from Grid] | S27: 0 | T27: 0 | U27: 0 | V27: 0 | W27: 0 | X27: 0 | Y27: 0 | Z27: 0 | AA27: 0
R28: MTH.200.C -> Transformation losses | S28: 0 | T28: 0 | U28: 0 | V28: 0 | W28: 0 | X28: 0 | Y28: 0 | Z28: 0 | AA28: 0
R29: NG | S29: 0 | T29: 0 | U29: 0 | V29: 44720 | W29: 0 | X29: 0 | Y29: 0 | Z29: 0 | AA29: 0
R30: NG [from Dist.] | S30: 0 | T30: 0 | U30: 0 | V30: 0 | W30: 0 | X30: 0 | Y30: 0 | Z30: 0 | AA30: 16640
R31: NG [from Wells] | S31: 0 | T31: 0 | U31: 0 | V31: 0 | W31: 42640 | X31: 0 | Y31: 0 | Z31: 0 | AA31: 0
... R33: Petrol [from Dist.] | S33: 0 | T33: 0 | U33: 0 | V33: 0 | W33: 0 | X33: 0 | Y33: 0 | Z33: 0 | AA33: 0
S34: U_feed
S37: Crude dist. | T37: Diesel dist. | U37: Elect. grid | V37: Gas wells & proc. | W37: NG dist. | X37: Oil fields | Y37: Oil refineries | Z37: Petrol dist. | AA37: Power plants | AE37: Irreversibilities | AF37: Residential | AG37: Transformation losses | AH37: Transport
R38: Crude | S38: 0 | T38: 0 | U38: 0 | V38: 0 | W38: 0 | X38: 53000 | Y38: 0 | Z38: 0 | AA38: 0 | AD38: Crude | AE38: 0 | AF38: 0 | AG38: 0 | AH38: 0
R39: Crude [from Dist.] | S39: 530 | T39: 0 | U39: 0 | V39: 0 | W39: 0 | X39: 0 | Y39: 49820 | Z39: 0 | AA39: 0 | AD39: Crude [from Dist.] | AE39: 0 | AF39: 0 | AG39: 0 | AH39: 0
R40: Crude [from Fields] | S40: 50350 | T40: 0 | U40: 0 | V40: 0 | W40: 0 | X40: 2650 | Y40: 0 | Z40: 0 | AA40: 0 | AD40: Crude [from Fields] | AE40: 0 | AF40: 0 | AG40: 0 | AH40: 0
R41: Destroyed exergy | S41: 0 | T41: 0 | U41: 0 | V41: 0 | W41: 0 | X41: 0 | Y41: 0 | Z41: 0 | AA41: 0 | AD41: Destroyed exergy | AE41: 14665.442 | AF41: 0 | AG41: 0 | AH41: 0
R42: Diesel | S42: 0 | T42: 16430 | U42: 0 | V42: 0 | W42: 0 | X42: 0 | Y42: 5300 | Z42: 0 | AA42: 0 | AD42: Diesel | AE42: 0 | AF42: 0 | AG42: 0 | AH42: 0
R43: Diesel [from Dist.] | S43: 26.5 | T43: 371 | U43: 0 | V43: 53 | W43: 26.5 | X43: 53 | Y43: 0 | Z43: 265 | AA43: 0 | AD43: Diesel [from Dist.] | AE43: 0 | AF43: 0 | AG43: 0 | AH43: 15635
R44: Elect | S44: 0 | T44: 0 | U44: 6400 | V44: 0 | W44: 0 | X44: 0 | Y44: 0 | Z44: 0 | AA44: 0 | AD44: Elect | AE44: 0 | AF44: 0 | AG44: 0 | AH44: 0
R45: Elect [from Grid] | S45: 25 | T45: 0 | U45: 0 | V45: 25 | W45: 25 | X45: 25 | Y45: 75 | Z45: 0 | AA45: 100 | AD45: Elect [from Grid] | AE45: 0 | AF45: 6000 | AG45: 0 | AH45: 0
R46: MTH.200.C -> Transformation losses | S46: 0 | T46: 0 | U46: 0 | V46: 0 | W46: 0 | X46: 0 | Y46: 0 | Z46: 0 | AA46: 0 | AD46: MTH.200.C -> Transformation losses | AE46: 0 | AF46: 0 | AG46: 7859.5584 | AH46: 0
...

Sheet Checks
A1: Original ECC | AP1: Calculate energy losses (waste heat) | BI1: Endogenize energy losses (waste heat) | CX1: Convert to exergy (XCC) | EM1: Calculate exergy losses (irreversibility) | FF1: Endogenize irreversibility (exergy destruction) | GU1: Compare to Recca results
B2: ktoe | S2: Crude dist. | T2: Diesel dist. | U2: Elect. grid | V2: Gas wells & proc. | W2: NG dist. | X2: Oil fields | Y2: Oil refineries | Z2: Petrol dist. | AA2: Power plants | AE2: Crude dist. | AF2: Diesel dist. | AG2: Elect. grid | AH2: Gas wells & proc. | AI2: NG dist. | AJ2: Oil fields | AK2: Oil refineries | AL2: Petrol dist. | AM2: Power plants | CA2: =S2 -> Crude dist. | CB2: =T2 -> Diesel dist. | CC2: =U2 -> Elect. grid | CD2: =V2 -> Gas wells & proc. | CE2: =W2 -> NG dist. | CF2: =X2 -> Oil fields | CG2: =Y2 -> Oil refineries | CH2: =Z2 -> Petrol dist. | CI2: =AA2 -> Power plants | CM2: =AE2 -> Crude dist. | CN2: =AF2 -> Diesel dist. | CO2: =AG2 -> Elect. grid | CP2: =AH2 -> Gas wells & proc. | CQ2: =AI2 -> NG dist. | CR2: =AJ2 -> Oil fields | CS2: =AK2 -> Oil refineries | CT2: =AL2 -> Petrol dist. | CU2: =AM2 -> Power plants | DP2: Crude dist. | DQ2: Diesel dist. | DR2: Elect. grid | DS2: Gas wells & proc. | DT2: NG dist. | DU2: Oil fields | DV2: Oil refineries | DW2: Petrol dist. | DX2: Power plants | EB2: Crude dist. | EC2: Diesel dist. | ED2: Elect. grid | EE2: Gas wells & proc. | EF2: NG dist. | EG2: Oil fields | EH2: Oil refineries | EI2: Petrol dist. | EJ2: Power plants | FX2: =DP2 -> Crude dist. | FY2: =DQ2 -> Diesel dist. | FZ2: =DR2 -> Elect. grid | GA2: =DS2 -> Gas wells & proc. | GB2: =DT2 -> NG dist. | GC2: =DU2 -> Oil fields | GD2: =DV2 -> Oil refineries | GE2: =DW2 -> Petrol dist. | GF2: =DX2 -> Power plants | GJ2: =EB2 -> Crude dist. | GK2: =EC2 -> Diesel dist. | GL2: =ED2 -> Elect. grid | GM2: =EE2 -> Gas wells & proc. | GN2: =EF2 -> NG dist. | GO2: =EG2 -> Oil fields | GP2: =EH2 -> Oil refineries | GQ2: =EI2 -> Petrol dist. | GR2: =EJ2 -> Power plants | HM2: Crude dist. | HN2: Diesel dist. | HO2: Elect. grid | HP2: Gas wells & proc. | HQ2: NG dist. | HR2: Oil fields | HS2: Oil refineries | HT2: Petrol dist. | HU2: Power plants | HY2: Crude dist. | HZ2: Diesel dist. | IA2: Elect. grid | IB2: Gas wells & proc. | IC2: NG dist. | ID2: Oil fields | IE2: Oil refineries | IF2: Petrol dist. | IG2: Power plants
A3: Crude | B3: 1 | R3: Crude | S3: 0 | T3: 0 | U3: 0 | V3: 0 | W3: 0 | X3: 0 | Y3: 0 | Z3: 0 | AA3: 0 | AD3: Crude | AE3: 0 | AF3: 0 | AG3: 0 | AH3: 0 | AI3: 0 | AJ3: 0 | AK3: 0 | AL3: 0 | AM3: 0 | BZ3: =R3 -> Crude | CA3: =S3 -> 0 | CB3: =T3 -> 0 | CC3: =U3 -> 0 | CD3: =V3 -> 0 | CE3: =W3 -> 0 | CF3: =X3 -> 0 | CG3: =Y3 -> 0 | ... CI3: =AA3 -> 0 | CL3: =AD3 -> Crude | CM3: =AE3 -> 0 | CN3: =AF3 -> 0 | CO3: =AG3 -> 0 | CP3: =AH3 -> 0 | CQ3: =AI3 -> 0 | CR3: =AJ3 -> 0 | CS3: =AK3 -> 0 | ... CU3: =AM3 -> 0 | DO3: Crude | DP3: 0 | DQ3: 0 | DR3: 0 | DS3: 0 | DT3: 0 | DU3: 0 | DV3: 0 | DW3: 0 | DX3: 0 | EA3: Crude | EB3: 0 | EC3: 0 | ED3: 0 | EE3: 0 | EF3: 0 | EG3: =DU3/DU39 -> 0 | EH3: 0 | EI3: 0 | EJ3: 0 | FW3: =DO3 -> Crude | FX3: =DP3 -> 0 | FY3: =DQ3 -> 0 | FZ3: =DR3 -> 0 | GA3: =DS3 -> 0 | GB3: =DT3 -> 0 | GC3: =DU3 -> 0 | GD3: =DV3 -> 0 | ... GF3: =DX3 -> 0 | GI3: =EA3 -> Crude | GJ3: =EB3 -> 0 | GK3: =EC3 -> 0 | GL3: =ED3 -> 0 | GM3: =EE3 -> 0 | GN3: =EF3 -> 0 | GO3: =EG3 -> 0 | GP3: =EH3 -> 0 | ... GR3: =EJ3 -> 0 | HL3: Crude | HM3: =FX3-X_Final_2000!S2 -> 0 | HN3: =FY3-X_Final_2000!T2 -> 0 | HO3: =FZ3-X_Final_2000!U2 -> 0 | HP3: =GA3-X_Final_2000!V2 -> 0 | HQ3: =GB3-X_Final_2000!W2 -> 0 | HR3: =GC3-X_Final_2000!X2 -> 0 | HS3: =GD3-X_Final_2000!Y2 -> 0 | HT3: =GE3-X_Final_2000!Z2 -> 0 | HU3: =GF3-X_Final_2000!AA2 -> 0 | HX3: Crude | HY3: =GJ3-X_Final_2000!AE2 -> 0 | HZ3: =GK3-X_Final_2000!AF2 -> 0 | IA3: =GL3-X_Final_2000!AG2 -> 0 | IB3: =GM3-X_Final_2000!AH2 -> 0 | IC3: =GN3-X_Final_2000!AI2 -> 0 | ID3: =GO3-X_Final_2000!AJ2 -> 0 | IE3: =GP3-X_Final_2000!AK2 -> 0 | IF3: =GQ3-X_Final_2000!AL2 -> 0 | IG3: =GR3-X_Final_2000!AM2 -> 0
A4: Crude [from Dist.] | B4: 1 | R4: Crude [from Dist.] | S4: 500 | T4: 0 | U4: 0 | V4: 0 | W4: 0 | X4: 0 | Y4: 0 | Z4: 0 | AA4: 0 | AD4: Crude [from Dist.] | AE4: 1 | AF4: 0 | AG4: 0 | AH4: 0 | AI4: 0 | AJ4: 0 | AK4: 0 | AL4: 0 | AM4: 0 | BZ4: =R4 -> Crude [from Dist.] | CA4: =S4 -> 500 | CB4: =T4 -> 0 | CC4: =U4 -> 0 | CD4: =V4 -> 0 | CE4: =W4 -> 0 | CF4: =X4 -> 0 | CG4: =Y4 -> 0 | ... CI4: =AA4 -> 0 | CL4: =AD4 -> Crude [from Dist.] | CM4: =AE4 -> 1 | CN4: =AF4 -> 0 | CO4: =AG4 -> 0 | CP4: =AH4 -> 0 | CQ4: =AI4 -> 0 | CR4: =AJ4 -> 0 | CS4: =AK4 -> 0 | ... CU4: =AM4 -> 0 | DO4: Crude [from Dist.] | DP4: =DP40 -> 530 | DQ4: 0 | DR4: 0 | DS4: 0 | DT4: 0 | DU4: 0 | DV4: 0 | DW4: 0 | DX4: 0 | EA4: Crude [from Dist.] | EB4: =DP4/DP40 -> 1 | EC4: 0 | ED4: 0 | EE4: 0 | EF4: 0 | EG4: 0 | EH4: =DV4/DV40 -> 0 | EI4: 0 | EJ4: 0 | FW4: =DO4 -> Crude [from Dist.] | FX4: =DP4 -> 530 | FY4: =DQ4 -> 0 | FZ4: =DR4 -> 0 | GA4: =DS4 -> 0 | GB4: =DT4 -> 0 | GC4: =DU4 -> 0 | GD4: =DV4 -> 0 | ... GF4: =DX4 -> 0 | GI4: =EA4 -> Crude [from Dist.] | GJ4: =EB4 -> 1 | GK4: =EC4 -> 0 | GL4: =ED4 -> 0 | GM4: =EE4 -> 0 | GN4: =EF4 -> 0 | GO4: =EG4 -> 0 | GP4: =EH4 -> 0 | ... GR4: =EJ4 -> 0 | HL4: Crude [from Dist.] | HM4: =FX4-X_Final_2000!S3 -> 0 | HN4: =FY4-X_Final_2000!T3 -> 0 | HO4: =FZ4-X_Final_2000!U3 -> 0 | HP4: =GA4-X_Final_2000!V3 -> 0 | HQ4: =GB4-X_Final_2000!W3 -> 0 | HR4: =GC4-X_Final_2000!X3 -> 0 | HS4: =GD4-X_Final_2000!Y3 -> 0 | HT4: =GE4-X_Final_2000!Z3 -> 0 | HU4: =GF4-X_Final_2000!AA3 -> 0 | HX4: Crude [from Dist.] | HY4: =GJ4-X_Final_2000!AE3 -> 0 | HZ4: =GK4-X_Final_2000!AF3 -> 0 | IA4: =GL4-X_Final_2000!AG3 -> 0 | IB4: =GM4-X_Final_2000!AH3 -> 0 | IC4: =GN4-X_Final_2000!AI3 -> 0 | ID4: =GO4-X_Final_2000!AJ3 -> 0 | IE4: =GP4-X_Final_2000!AK3 -> 0 | IF4: =GQ4-X_Final_2000!AL3 -> 0 | IG4: =GR4-X_Final_2000!AM3 -> 0
A5: Crude [from Fields] | B5: 1 | R5: Crude [from Fields] | S5: 0 | T5: 0 | U5: 0 | V5: 0 | W5: 0 | X5: 2500 | Y5: 0 | Z5: 0 | AA5: 0 | AD5: Crude [from Fields] | AE5: 0 | AF5: 0 | AG5: 0 | AH5: 0 | AI5: 0 | AJ5: 1 | AK5: 0 | AL5: 0 | AM5: 0 | BZ5: =R5 -> Crude [from Fields] | CA5: =S5 -> 0 | CB5: =T5 -> 0 | CC5: =U5 -> 0 | CD5: =V5 -> 0 | CE5: =W5 -> 0 | CF5: =X5 -> 2500 | CG5: =Y5 -> 0 | ... CI5: =AA5 -> 0 | CL5: =AD5 -> Crude [from Fields] | CM5: =AE5 -> 0 | CN5: =AF5 -> 0 | CO5: =AG5 -> 0 | CP5: =AH5 -> 0 | CQ5: =AI5 -> 0 | CR5: =AJ5 -> 1 | CS5: =AK5 -> 0 | ... CU5: =AM5 -> 0 | DO5: Crude [from Fields] | DP5: 0 | DQ5: 0 | DR5: 0 | DS5: 0 | DT5: 0 | DU5: =DU41 -> 2650 | DV5: 0 | DW5: 0 | DX5: 0 | EA5: Crude [from Fields] | EB5: =DP5/DP41 -> 0 | EC5: 0 | ED5: 0 | EE5: 0 | EF5: 0 | EG5: =DU5/DU41 -> 1 | EH5: 0 | EI5: 0 | EJ5: 0 | FW5: =DO5 -> Crude [from Fields] | FX5: =DP5 -> 0 | FY5: =DQ5 -> 0 | FZ5: =DR5 -> 0 | GA5: =DS5 -> 0 | GB5: =DT5 -> 0 | GC5: =DU5 -> 2650 | GD5: =DV5 -> 0 | ... GF5: =DX5 -> 0 | GI5: =EA5 -> Crude [from Fields] | GJ5: =EB5 -> 0 | GK5: =EC5 -> 0 | GL5: =ED5 -> 0 | GM5: =EE5 -> 0 | GN5: =EF5 -> 0 | GO5: =EG5 -> 1 | GP5: =EH5 -> 0 | ... GR5: =EJ5 -> 0 | HL5: Crude [from Fields] | HM5: =FX5-X_Final_2000!S4 -> 0 | HN5: =FY5-X_Final_2000!T4 -> 0 | HO5: =FZ5-X_Final_2000!U4 -> 0 | HP5: =GA5-X_Final_2000!V4 -> 0 | HQ5: =GB5-X_Final_2000!W4 -> 0 | HR5: =GC5-X_Final_2000!X4 -> 0 | HS5: =GD5-X_Final_2000!Y4 -> 0 | HT5: =GE5-X_Final_2000!Z4 -> 0 | HU5: =GF5-X_Final_2000!AA4 -> 0 | HX5: Crude [from Fields] | HY5: =GJ5-X_Final_2000!AE4 -> 0 | HZ5: =GK5-X_Final_2000!AF4 -> 0 | IA5: =GL5-X_Final_2000!AG4 -> 0 | IB5: =GM5-X_Final_2000!AH4 -> 0 | IC5: =GN5-X_Final_2000!AI4 -> 0 | ID5: =GO5-X_Final_2000!AJ4 -> 0 | IE5: =GP5-X_Final_2000!AK4 -> 0 | IF5: =GQ5-X_Final_2000!AL4 -> 0 | IG5: =GR5-X_Final_2000!AM4 -> 0
A6: Destroyed exergy | B6: 1 | R6: Destroyed exergy | S6: 0 | T6: 0 | U6: 0 | V6: 0 | W6: 0 | X6: 0 | Y6: 0 | Z6: 0 | AA6: 0 | AD6: Destroyed exergy | AE6: 0 | AF6: 0 | AG6: 0 | AH6: 0 | AI6: 0 | AJ6: 0 | AK6: 0 | AL6: 0 | AM6: 0 | BZ6: Destroyed exergy | CA6: =S6 -> 0 | CB6: =T6 -> 0 | CC6: =U6 -> 0 | CD6: =V6 -> 0 | CE6: =W6 -> 0 | CF6: =X6 -> 0 | CG6: =Y6 -> 0 | CH6: =Z6 -> 0 | CI6: =AA6 -> 0 | CL6: Destroyed exergy | CM6: =AE6 -> 0 | CN6: =AF6 -> 0 | CO6: =AG6 -> 0 | CP6: =AH6 -> 0 | CQ6: =AI6 -> 0 | CR6: =AJ6 -> 0 | CS6: =AK6 -> 0 | CT6: =AL6 -> 0 | CU6: =AM6 -> 0 | DO6: Destroyed exergy | DP6: 0 | DQ6: 0 | DR6: 0 | DS6: 0 | DT6: 0 | DU6: 0 | DV6: 0 | DW6: 0 | DX6: 0 | EA6: Destroyed exergy | EB6: 0 | EC6: 0 | ED6: 0 | EE6: 0 | EF6: 0 | EG6: 0 | EH6: 0 | EI6: 0 | EJ6: 0 | FW6: =DO6 -> Destroyed exergy | FX6: =DP6 -> 0 | FY6: =DQ6 -> 0 | FZ6: =DR6 -> 0 | GA6: =DS6 -> 0 | GB6: =DT6 -> 0 | GC6: =DU6 -> 0 | GD6: =DV6 -> 0 | ... GF6: =DX6 -> 0 | GI6: =EA6 -> Destroyed exergy | GJ6: =EB6 -> 0 | GK6: =EC6 -> 0 | GL6: =ED6 -> 0 | GM6: =EE6 -> 0 | GN6: =EF6 -> 0 | GO6: =EG6 -> 0 | GP6: =EH6 -> 0 | ... GR6: =EJ6 -> 0 | HL6: Destroyed exergy | HM6: =FX6-X_Final_2000!S5 -> 0 | HN6: =FY6-X_Final_2000!T5 -> 0 | HO6: =FZ6-X_Final_2000!U5 -> 0 | HP6: =GA6-X_Final_2000!V5 -> 0 | HQ6: =GB6-X_Final_2000!W5 -> 0 | HR6: =GC6-X_Final_2000!X5 -> 0 | HS6: =GD6-X_Final_2000!Y5 -> 0 | HT6: =GE6-X_Final_2000!Z5 -> 0 | HU6: =GF6-X_Final_2000!AA5 -> 0 | HX6: Destroyed exergy | HY6: =GJ6-X_Final_2000!AE5 -> 0 | HZ6: =GK6-X_Final_2000!AF5 -> 0 | IA6: =GL6-X_Final_2000!AG5 -> 0 | IB6: =GM6-X_Final_2000!AH5 -> 0 | IC6: =GN6-X_Final_2000!AI5 -> 0 | ID6: =GO6-X_Final_2000!AJ5 -> 0 | IE6: =GP6-X_Final_2000!AK5 -> 0 | IF6: =GQ6-X_Final_2000!AL5 -> 0 | IG6: =GR6-X_Final_2000!AM5 -> 0
A7: Diesel | B7: 1 | R7: Diesel | S7: 0 | T7: 0 | U7: 0 | V7: 0 | W7: 0 | X7: 0 | Y7: 5000 | Z7: 0 | AA7: 0 | AD7: Diesel | AE7: 0 | AF7: 0 | AG7: 0 | AH7: 0 | AI7: 0 | AJ7: 0 | AK7: 1 | AL7: 0 | AM7: 0 | BZ7: =R7 -> Diesel | CA7: =S7 -> 0 | CB7: =T7 -> 0 | CC7: =U7 -> 0 | CD7: =V7 -> 0 | CE7: =W7 -> 0 | CF7: =X7 -> 0 | CG7: =Y7 -> 5000 | ... CI7: =AA7 -> 0 | CL7: =AD7 -> Diesel | CM7: =AE7 -> 0 | CN7: =AF7 -> 0 | CO7: =AG7 -> 0 | CP7: =AH7 -> 0 | CQ7: =AI7 -> 0 | CR7: =AJ7 -> 0 | CS7: =AK7 -> 1 | ... CU7: =AM7 -> 0 | DO7: Diesel | DP7: 0 | DQ7: 0 | DR7: 0 | DS7: 0 | DT7: 0 | DU7: 0 | DV7: =DV43 -> 5300 | DW7: 0 | DX7: 0 | EA7: Diesel | EB7: 0 | EC7: =DQ7/DQ43 -> 0 | ED7: 0 | EE7: 0 | EF7: 0 | EG7: 0 | EH7: =DV7/DV43 -> 1 | EI7: 0 | EJ7: 0 | FW7: =DO7 -> Diesel | FX7: =DP7 -> 0 | FY7: =DQ7 -> 0 | FZ7: =DR7 -> 0 | GA7: =DS7 -> 0 | GB7: =DT7 -> 0 | GC7: =DU7 -> 0 | GD7: =DV7 -> 5300 | ... GF7: =DX7 -> 0 | GI7: =EA7 -> Diesel | GJ7: =EB7 -> 0 | GK7: =EC7 -> 0 | GL7: =ED7 -> 0 | GM7: =EE7 -> 0 | GN7: =EF7 -> 0 | GO7: =EG7 -> 0 | GP7: =EH7 -> 1 | ... GR7: =EJ7 -> 0 | HL7: Diesel | HM7: =FX7-X_Final_2000!S6 -> 0 | HN7: =FY7-X_Final_2000!T6 -> 0 | HO7: =FZ7-X_Final_2000!U6 -> 0 | HP7: =GA7-X_Final_2000!V6 -> 0 | HQ7: =GB7-X_Final_2000!W6 -> 0 | HR7: =GC7-X_Final_2000!X6 -> 0 | HS7: =GD7-X_Final_2000!Y6 -> 0 | HT7: =GE7-X_Final_2000!Z6 -> 0 | HU7: =GF7-X_Final_2000!AA6 -> 0 | HX7: Diesel | HY7: =GJ7-X_Final_2000!AE6 -> 0 | HZ7: =GK7-X_Final_2000!AF6 -> 0 | IA7: =GL7-X_Final_2000!AG6 -> 0 | IB7: =GM7-X_Final_2000!AH6 -> 0 | IC7: =GN7-X_Final_2000!AI6 -> 0 | ID7: =GO7-X_Final_2000!AJ6 -> 0 | IE7: =GP7-X_Final_2000!AK6 -> 0 | IF7: =GQ7-X_Final_2000!AL6 -> 0 | IG7: =GR7-X_Final_2000!AM6 -> 0
A8: Diesel [from Dist.] | B8: 1 | R8: Diesel [from Dist.] | S8: 25 | T8: 350 | U8: 0 | V8: 50 | W8: 25 | X8: 50 | Y8: 0 | Z8: 250 | AA8: 0 | AD8: Diesel [from Dist.] | AE8: 1 | AF8: 1 | AG8: 0 | AH8: 1 | AI8: 1 | AJ8: 1 | AK8: 0 | AL8: 1 | AM8: 0 | BZ8: =R8 -> Diesel [from Dist.] | CA8: =S8 -> 25 | CB8: =T8 -> 350 | CC8: =U8 -> 0 | CD8: =V8 -> 50 | CE8: =W8 -> 25 | CF8: =X8 -> 50 | CG8: =Y8 -> 0 | ... CI8: =AA8 -> 0 | CL8: =AD8 -> Diesel [from Dist.] | CM8: =AE8 -> 1 | CN8: =AF8 -> 1 | CO8: =AG8 -> 0 | CP8: =AH8 -> 1 | CQ8: =AI8 -> 1 | CR8: =AJ8 -> 1 | CS8: =AK8 -> 0 | ... CU8: =AM8 -> 0 | DO8: Diesel [from Dist.] | DP8: =DP44 -> 26.5 | DQ8: =DQ44 -> 371 | DR8: =DR44 -> 0 | DS8: =DS44 -> 53 | DT8: =DT44 -> 26.5 | DU8: =DU44 -> 53 | DV8: =DV44 -> 0 | DW8: =DW44 -> 265 | DX8: =DX44 -> 0 | EA8: Diesel [from Dist.] | EB8: =DP8/DP44 -> 1 | EC8: =DQ8/DQ44 -> 1 | ED8: 0 | EE8: =DS8/DS44 -> 1 | EF8: =DT8/DT44 -> 1 | EG8: =DU8/DU44 -> 1 | EH8: 0 | EI8: =DW8/DW44 -> 1 | EJ8: 0 | FW8: =DO8 -> Diesel [from Dist.] | FX8: =DP8 -> 26.5 | FY8: =DQ8 -> 371 | FZ8: =DR8 -> 0 | GA8: =DS8 -> 53 | GB8: =DT8 -> 26.5 | GC8: =DU8 -> 53 | GD8: =DV8 -> 0 | ... GF8: =DX8 -> 0 | GI8: =EA8 -> Diesel [from Dist.] | GJ8: =EB8 -> 1 | GK8: =EC8 -> 1 | GL8: =ED8 -> 0 | GM8: =EE8 -> 1 | GN8: =EF8 -> 1 | GO8: =EG8 -> 1 | GP8: =EH8 -> 0 | ... GR8: =EJ8 -> 0 | HL8: Diesel [from Dist.] | HM8: =FX8-X_Final_2000!S7 -> 0 | HN8: =FY8-X_Final_2000!T7 -> 0 | HO8: =FZ8-X_Final_2000!U7 -> 0 | HP8: =GA8-X_Final_2000!V7 -> 0 | HQ8: =GB8-X_Final_2000!W7 -> 0 | HR8: =GC8-X_Final_2000!X7 -> 0 | HS8: =GD8-X_Final_2000!Y7 -> 0 | HT8: =GE8-X_Final_2000!Z7 -> 0 | HU8: =GF8-X_Final_2000!AA7 -> 0 | HX8: Diesel [from Dist.] | HY8: =GJ8-X_Final_2000!AE7 -> 0 | HZ8: =GK8-X_Final_2000!AF7 -> 0 | IA8: =GL8-X_Final_2000!AG7 -> 0 | IB8: =GM8-X_Final_2000!AH7 -> 0 | IC8: =GN8-X_Final_2000!AI7 -> 0 | ID8: =GO8-X_Final_2000!AJ7 -> 0 | IE8: =GP8-X_Final_2000!AK7 -> 0 | IF8: =GQ8-X_Final_2000!AL7 -> 0 | IG8: =GR8-X_Final_2000!AM7 -> 0
A9: Elect | B9: 1 | R9: Elect | S9: 0 | T9: 0 | U9: 0 | V9: 0 | W9: 0 | X9: 0 | Y9: 0 | Z9: 0 | AA9: 0 | AD9: Elect | AE9: 0 | AF9: 0 | AG9: 0 | AH9: 0 | AI9: 0 | AJ9: 0 | AK9: 0 | AL9: 0 | AM9: 0 | BZ9: =R9 -> Elect | CA9: =S9 -> 0 | CB9: =T9 -> 0 | CC9: =U9 -> 0 | CD9: =V9 -> 0 | CE9: =W9 -> 0 | CF9: =X9 -> 0 | CG9: =Y9 -> 0 | ... CI9: =AA9 -> 0 | CL9: =AD9 -> Elect | CM9: =AE9 -> 0 | CN9: =AF9 -> 0 | CO9: =AG9 -> 0 | CP9: =AH9 -> 0 | CQ9: =AI9 -> 0 | CR9: =AJ9 -> 0 | CS9: =AK9 -> 0 | ... CU9: =AM9 -> 0 | DO9: Elect | DP9: 0 | DQ9: 0 | DR9: 0 | DS9: 0 | DT9: 0 | DU9: 0 | DV9: 0 | DW9: 0 | DX9: 0 | EA9: Elect | EB9: 0 | EC9: 0 | ED9: =DR9/DR45 -> 0 | EE9: 0 | EF9: 0 | EG9: 0 | EH9: 0 | EI9: 0 | EJ9: 0 | FW9: =DO9 -> Elect | FX9: =DP9 -> 0 | FY9: =DQ9 -> 0 | FZ9: =DR9 -> 0 | GA9: =DS9 -> 0 | GB9: =DT9 -> 0 | GC9: =DU9 -> 0 | GD9: =DV9 -> 0 | ... GF9: =DX9 -> 0 | GI9: =EA9 -> Elect | GJ9: =EB9 -> 0 | GK9: =EC9 -> 0 | GL9: =ED9 -> 0 | GM9: =EE9 -> 0 | GN9: =EF9 -> 0 | GO9: =EG9 -> 0 | GP9: =EH9 -> 0 | ... GR9: =EJ9 -> 0 | HL9: Elect | HM9: =FX9-X_Final_2000!S8 -> 0 | HN9: =FY9-X_Final_2000!T8 -> 0 | HO9: =FZ9-X_Final_2000!U8 -> 0 | HP9: =GA9-X_Final_2000!V8 -> 0 | HQ9: =GB9-X_Final_2000!W8 -> 0 | HR9: =GC9-X_Final_2000!X8 -> 0 | HS9: =GD9-X_Final_2000!Y8 -> 0 | HT9: =GE9-X_Final_2000!Z8 -> 0 | HU9: =GF9-X_Final_2000!AA8 -> 0 | HX9: Elect | HY9: =GJ9-X_Final_2000!AE8 -> 0 | HZ9: =GK9-X_Final_2000!AF8 -> 0 | IA9: =GL9-X_Final_2000!AG8 -> 0 | IB9: =GM9-X_Final_2000!AH8 -> 0 | IC9: =GN9-X_Final_2000!AI8 -> 0 | ID9: =GO9-X_Final_2000!AJ8 -> 0 | IE9: =GP9-X_Final_2000!AK8 -> 0 | IF9: =GQ9-X_Final_2000!AL8 -> 0 | IG9: =GR9-X_Final_2000!AM8 -> 0
A10: Elect [from Grid] | B10: 1 | R10: Elect [from Grid] | S10: 25 | T10: 0 | U10: 0 | V10: 25 | W10: 25 | X10: 25 | Y10: 75 | Z10: 0 | AA10: 100 | AD10: Elect [from Grid] | AE10: 1 | AF10: 0 | AG10: 0 | AH10: 1 | AI10: 1 | AJ10: 1 | AK10: 1 | AL10: 0 | AM10: 1 | BZ10: =R10 -> Elect [from Grid] | CA10: =S10 -> 25 | CB10: =T10 -> 0 | CC10: =U10 -> 0 | CD10: =V10 -> 25 | CE10: =W10 -> 25 | CF10: =X10 -> 25 | CG10: =Y10 -> 75 | ... CI10: =AA10 -> 100 | CL10: =AD10 -> Elect [from Grid] | CM10: =AE10 -> 1 | CN10: =AF10 -> 0 | CO10: =AG10 -> 0 | CP10: =AH10 -> 1 | CQ10: =AI10 -> 1 | CR10: =AJ10 -> 1 | CS10: =AK10 -> 1 | ... CU10: =AM10 -> 1 | DO10: Elect [from Grid] | DP10: =DP46 -> 25 | DQ10: =DQ46 -> 0 | DR10: =DR46 -> 0 | DS10: =DS46 -> 25 | DT10: =DT46 -> 25 | DU10: =DU46 -> 25 | DV10: =DV46 -> 75 | DW10: =DW46 -> 0 | DX10: =DX46 -> 100 | EA10: Elect [from Grid] | EB10: =DP10/DP46 -> 1 | EC10: 0 | ED10: 0 | EE10: =DS10/DS46 -> 1 | EF10: =DT10/DT46 -> 1 | EG10: =DU10/DU46 -> 1 | EH10: =DV10/DV46 -> 1 | EI10: 0 | EJ10: =DX10/DX46 -> 1 | FW10: =DO10 -> Elect [from Grid] | FX10: =DP10 -> 25 | FY10: =DQ10 -> 0 | FZ10: =DR10 -> 0 | GA10: =DS10 -> 25 | GB10: =DT10 -> 25 | GC10: =DU10 -> 25 | GD10: =DV10 -> 75 | ... GF10: =DX10 -> 100 | GI10: =EA10 -> Elect [from Grid] | GJ10: =EB10 -> 1 | GK10: =EC10 -> 0 | GL10: =ED10 -> 0 | GM10: =EE10 -> 1 | GN10: =EF10 -> 1 | GO10: =EG10 -> 1 | GP10: =EH10 -> 1 | ... GR10: =EJ10 -> 1 | HL10: Elect [from Grid] | HM10: =FX10-X_Final_2000!S9 -> 0 | HN10: =FY10-X_Final_2000!T9 -> 0 | HO10: =FZ10-X_Final_2000!U9 -> 0 | HP10: =GA10-X_Final_2000!V9 -> 0 | HQ10: =GB10-X_Final_2000!W9 -> 0 | HR10: =GC10-X_Final_2000!X9 -> 0 | HS10: =GD10-X_Final_2000!Y9 -> 0 | HT10: =GE10-X_Final_2000!Z9 -> 0 | HU10: =GF10-X_Final_2000!AA9 -> 0 | HX10: Elect [from Grid] | HY10: =GJ10-X_Final_2000!AE9 -> 0 | HZ10: =GK10-X_Final_2000!AF9 -> 0 | IA10: =GL10-X_Final_2000!AG9 -> 0 | IB10: =GM10-X_Final_2000!AH9 -> 0 | IC10: =GN10-X_Final_2000!AI9 -> 0 | ID10: =GO10-X_Final_2000!AJ9 -> 0 | IE10: =GP10-X_Final_2000!AK9 -> 0 | IF10: =GQ10-X_Final_2000!AL9 -> 0 | IG10: =GR10-X_Final_2000!AM9 -> 0
A11: MTH.200.C -> Transformation losses | B11: 1 | R11: MTH.200.C -> Transformation losses | S11: 0 | T11: 0 | U11: 0 | V11: 0 | W11: 0 | X11: 0 | Y11: 0 | Z11: 0 | AA11: 0 | AD11: MTH.200.C -> Transformation losses | AE11: 0 | AF11: 0 | AG11: 0 | AH11: 0 | AI11: 0 | AJ11: 0 | AK11: 0 | AL11: 0 | AM11: 0 | BZ11: =R11 -> MTH.200.C -> Transformation losses | CA11: =S11 -> 0 | CB11: =T11 -> 0 | CC11: =U11 -> 0 | CD11: =V11 -> 0 | CE11: =W11 -> 0 | CF11: =X11 -> 0 | CG11: =Y11 -> 0 | ... CI11: =AA11 -> 0 | CL11: =AD11 -> MTH.200.C -> Transformation losses | CM11: =AE11 -> 0 | CN11: =AF11 -> 0 | CO11: =AG11 -> 0 | CP11: =AH11 -> 0 | CQ11: =AI11 -> 0 | CR11: =AJ11 -> 0 | CS11: =AK11 -> 0 | ... CU11: =AM11 -> 0 | DO11: MTH.200.C -> Transformation losses | DP11: 0 | DQ11: 0 | DR11: 0 | DS11: 0 | DT11: 0 | DU11: 0 | DV11: 0 | DW11: 0 | DX11: 0 | EA11: MTH.200.C -> Transformation losses | EB11: 0 | EC11: 0 | ED11: 0 | EE11: 0 | EF11: 0 | EG11: 0 | EH11: 0 | EI11: 0 | EJ11: 0 | FW11: =DO11 -> MTH.200.C -> Transformation losses | FX11: =DP11 -> 0 | FY11: =DQ11 -> 0 | FZ11: =DR11 -> 0 | GA11: =DS11 -> 0 | GB11: =DT11 -> 0 | GC11: =DU11 -> 0 | GD11: =DV11 -> 0 | ... GF11: =DX11 -> 0 | GI11: =EA11 -> MTH.200.C -> Transformation losses | GJ11: =EB11 -> 0 | GK11: =EC11 -> 0 | GL11: =ED11 -> 0 | GM11: =EE11 -> 0 | GN11: =EF11 -> 0 | GO11: =EG11 -> 0 | GP11: =EH11 -> 0 | ... GR11: =EJ11 -> 0 | HL11: MTH.200.C -> Transformation losses | HM11: =FX11-X_Final_2000!S10 -> 0 | HN11: =FY11-X_Final_2000!T10 -> 0 | HO11: =FZ11-X_Final_2000!U10 -> 0 | HP11: =GA11-X_Final_2000!V10 -> 0 | HQ11: =GB11-X_Final_2000!W10 -> 0 | HR11: =GC11-X_Final_2000!X10 -> 0 | HS11: =GD11-X_Final_2000!Y10 -> 0 | HT11: =GE11-X_Final_2000!Z10 -> 0 | HU11: =GF11-X_Final_2000!AA10 -> 0 | HX11: MTH.200.C -> Transformation losses | HY11: =GJ11-X_Final_2000!AE10 -> 0 | HZ11: =GK11-X_Final_2000!AF10 -> 0 | IA11: =GL11-X_Final_2000!AG10 -> 0 | IB11: =GM11-X_Final_2000!AH10 -> 0 | IC11: =GN11-X_Final_2000!AI10 -> 0 | ID11: =GO11-X_Final_2000!AJ10 -> 0 | IE11: =GP11-X_Final_2000!AK10 -> 0 | IF11: =GQ11-X_Final_2000!AL10 -> 0 | IG11: =GR11-X_Final_2000!AM10 -> 0
A12: NG | B12: 1 | R12: NG | S12: 0 | T12: 0 | U12: 0 | V12: 0 | W12: 0 | X12: 0 | Y12: 0 | Z12: 0 | AA12: 0 | AD12: NG | AE12: 0 | AF12: 0 | AG12: 0 | AH12: 0 | AI12: 0 | AJ12: 0 | AK12: 0 | AL12: 0 | AM12: 0 | BZ12: =R12 -> NG | CA12: =S12 -> 0 | CB12: =T12 -> 0 | CC12: =U12 -> 0 | CD12: =V12 -> 0 | CE12: =W12 -> 0 | CF12: =X12 -> 0 | CG12: =Y12 -> 0 | ... CI12: =AA12 -> 0 | CL12: =AD12 -> NG | CM12: =AE12 -> 0 | CN12: =AF12 -> 0 | CO12: =AG12 -> 0 | CP12: =AH12 -> 0 | CQ12: =AI12 -> 0 | CR12: =AJ12 -> 0 | CS12: =AK12 -> 0 | ... CU12: =AM12 -> 0 | DO12: NG | DP12: 0 | DQ12: 0 | DR12: 0 | DS12: 0 | DT12: 0 | DU12: 0 | DV12: 0 | DW12: 0 | DX12: 0 | EA12: NG | EB12: 0 | EC12: 0 | ED12: 0 | EE12: =DS12/DS48 -> 0 | EF12: 0 | EG12: 0 | EH12: 0 | EI12: 0 | EJ12: 0 | FW12: =DO12 -> NG | FX12: =DP12 -> 0 | FY12: =DQ12 -> 0 | FZ12: =DR12 -> 0 | GA12: =DS12 -> 0 | GB12: =DT12 -> 0 | GC12: =DU12 -> 0 | GD12: =DV12 -> 0 | ... GF12: =DX12 -> 0 | GI12: =EA12 -> NG | GJ12: =EB12 -> 0 | GK12: =EC12 -> 0 | GL12: =ED12 -> 0 | GM12: =EE12 -> 0 | GN12: =EF12 -> 0 | GO12: =EG12 -> 0 | GP12: =EH12 -> 0 | ... GR12: =EJ12 -> 0 | HL12: NG | HM12: =FX12-X_Final_2000!S11 -> 0 | HN12: =FY12-X_Final_2000!T11 -> 0 | HO12: =FZ12-X_Final_2000!U11 -> 0 | HP12: =GA12-X_Final_2000!V11 -> 0 | HQ12: =GB12-X_Final_2000!W11 -> 0 | HR12: =GC12-X_Final_2000!X11 -> 0 | HS12: =GD12-X_Final_2000!Y11 -> 0 | HT12: =GE12-X_Final_2000!Z11 -> 0 | HU12: =GF12-X_Final_2000!AA11 -> 0 | HX12: NG | HY12: =GJ12-X_Final_2000!AE11 -> 0 | HZ12: =GK12-X_Final_2000!AF11 -> 0 | IA12: =GL12-X_Final_2000!AG11 -> 0 | IB12: =GM12-X_Final_2000!AH11 -> 0 | IC12: =GN12-X_Final_2000!AI11 -> 0 | ID12: =GO12-X_Final_2000!AJ11 -> 0 | IE12: =GP12-X_Final_2000!AK11 -> 0 | IF12: =GQ12-X_Final_2000!AL11 -> 0 | IG12: =GR12-X_Final_2000!AM11 -> 0
A13: NG [from Dist.] | B13: 1 | R13: NG [from Dist.] | S13: 0 | T13: 0 | U13: 0 | V13: 0 | W13: 0 | X13: 0 | Y13: 0 | Z13: 0 | AA13: 0 | AD13: NG [from Dist.] | AE13: 0 | AF13: 0 | AG13: 0 | AH13: 0 | AI13: 0 | AJ13: 0 | AK13: 0 | AL13: 0 | AM13: 0 | BZ13: =R13 -> NG [from Dist.] | CA13: =S13 -> 0 | CB13: =T13 -> 0 | CC13: =U13 -> 0 | CD13: =V13 -> 0 | CE13: =W13 -> 0 | CF13: =X13 -> 0 | CG13: =Y13 -> 0 | ... CI13: =AA13 -> 0 | CL13: =AD13 -> NG [from Dist.] | CM13: =AE13 -> 0 | CN13: =AF13 -> 0 | CO13: =AG13 -> 0 | CP13: =AH13 -> 0 | CQ13: =AI13 -> 0 | CR13: =AJ13 -> 0 | CS13: =AK13 -> 0 | ... CU13: =AM13 -> 0 | DO13: NG [from Dist.] | DP13: 0 | DQ13: 0 | DR13: 0 | DS13: 0 | DT13: 0 | DU13: 0 | DV13: 0 | DW13: 0 | DX13: 0 | EA13: NG [from Dist.] | EB13: 0 | EC13: 0 | ED13: 0 | EE13: 0 | EF13: 0 | EG13: 0 | EH13: 0 | EI13: 0 | EJ13: =DX13/DX49 -> 0 | FW13: =DO13 -> NG [from Dist.] | FX13: =DP13 -> 0 | FY13: =DQ13 -> 0 | FZ13: =DR13 -> 0 | GA13: =DS13 -> 0 | GB13: =DT13 -> 0 | GC13: =DU13 -> 0 | GD13: =DV13 -> 0 | ... GF13: =DX13 -> 0 | GI13: =EA13 -> NG [from Dist.] | GJ13: =EB13 -> 0 | GK13: =EC13 -> 0 | GL13: =ED13 -> 0 | GM13: =EE13 -> 0 | GN13: =EF13 -> 0 | GO13: =EG13 -> 0 | GP13: =EH13 -> 0 | ... GR13: =EJ13 -> 0 | HL13: NG [from Dist.] | HM13: =FX13-X_Final_2000!S12 -> 0 | HN13: =FY13-X_Final_2000!T12 -> 0 | HO13: =FZ13-X_Final_2000!U12 -> 0 | HP13: =GA13-X_Final_2000!V12 -> 0 | HQ13: =GB13-X_Final_2000!W12 -> 0 | HR13: =GC13-X_Final_2000!X12 -> 0 | HS13: =GD13-X_Final_2000!Y12 -> 0 | HT13: =GE13-X_Final_2000!Z12 -> 0 | HU13: =GF13-X_Final_2000!AA12 -> 0 | HX13: NG [from Dist.] | HY13: =GJ13-X_Final_2000!AE12 -> 0 | HZ13: =GK13-X_Final_2000!AF12 -> 0 | IA13: =GL13-X_Final_2000!AG12 -> 0 | IB13: =GM13-X_Final_2000!AH12 -> 0 | IC13: =GN13-X_Final_2000!AI12 -> 0 | ID13: =GO13-X_Final_2000!AJ12 -> 0 | IE13: =GP13-X_Final_2000!AK12 -> 0 | IF13: =GQ13-X_Final_2000!AL12 -> 0 | IG13: =GR13-X_Final_2000!AM12 -> 0
A14: NG [from Wells] | B14: 1 | R14: NG [from Wells] | S14: 0 | T14: 0 | U14: 0 | V14: 2000 | W14: 0 | X14: 0 | Y14: 0 | Z14: 0 | AA14: 0 | AD14: NG [from Wells] | AE14: 0 | AF14: 0 | AG14: 0 | AH14: 1 | AI14: 0 | AJ14: 0 | AK14: 0 | AL14: 0 | AM14: 0 | BZ14: =R14 -> NG [from Wells] | CA14: =S14 -> 0 | CB14: =T14 -> 0 | CC14: =U14 -> 0 | CD14: =V14 -> 2000 | CE14: =W14 -> 0 | CF14: =X14 -> 0 | CG14: =Y14 -> 0 | ... CI14: =AA14 -> 0 | CL14: =AD14 -> NG [from Wells] | CM14: =AE14 -> 0 | CN14: =AF14 -> 0 | CO14: =AG14 -> 0 | CP14: =AH14 -> 1 | CQ14: =AI14 -> 0 | CR14: =AJ14 -> 0 | CS14: =AK14 -> 0 | ... CU14: =AM14 -> 0 | DO14: NG [from Wells] | DP14: 0 | DQ14: 0 | DR14: 0 | DS14: =DS50 -> 2080 | DT14: 0 | DU14: 0 | DV14: 0 | DW14: 0 | DX14: 0 | EA14: NG [from Wells] | EB14: 0 | EC14: 0 | ED14: 0 | EE14: =DS14/DS50 -> 1 | EF14: =DT14/DT50 -> 0 | EG14: 0 | EH14: 0 | EI14: 0 | EJ14: 0 | FW14: =DO14 -> NG [from Wells] | FX14: =DP14 -> 0 | FY14: =DQ14 -> 0 | FZ14: =DR14 -> 0 | GA14: =DS14 -> 2080 | GB14: =DT14 -> 0 | GC14: =DU14 -> 0 | GD14: =DV14 -> 0 | ... GF14: =DX14 -> 0 | GI14: =EA14 -> NG [from Wells] | GJ14: =EB14 -> 0 | GK14: =EC14 -> 0 | GL14: =ED14 -> 0 | GM14: =EE14 -> 1 | GN14: =EF14 -> 0 | GO14: =EG14 -> 0 | GP14: =EH14 -> 0 | ... GR14: =EJ14 -> 0 | HL14: NG [from Wells] | HM14: =FX14-X_Final_2000!S13 -> 0 | HN14: =FY14-X_Final_2000!T13 -> 0 | HO14: =FZ14-X_Final_2000!U13 -> 0 | HP14: =GA14-X_Final_2000!V13 -> 0 | HQ14: =GB14-X_Final_2000!W13 -> 0 | HR14: =GC14-X_Final_2000!X13 -> 0 | HS14: =GD14-X_Final_2000!Y13 -> 0 | HT14: =GE14-X_Final_2000!Z13 -> 0 | HU14: =GF14-X_Final_2000!AA13 -> 0 | HX14: NG [from Wells] | HY14: =GJ14-X_Final_2000!AE13 -> 0 | HZ14: =GK14-X_Final_2000!AF13 -> 0 | IA14: =GL14-X_Final_2000!AG13 -> 0 | IB14: =GM14-X_Final_2000!AH13 -> 0 | IC14: =GN14-X_Final_2000!AI13 -> 0 | ID14: =GO14-X_Final_2000!AJ13 -> 0 | IE14: =GP14-X_Final_2000!AK13 -> 0 | IF14: =GQ14-X_Final_2000!AL13 -> 0 | IG14: =GR14-X_Final_2000!AM13 -> 0
A15: Petrol | B15: 1 | R15: Petrol | S15: 0 | T15: 0 | U15: 0 | V15: 0 | W15: 0 | X15: 0 | Y15: 0 | Z15: 0 | AA15: 0 | AD15: Petrol | AE15: 0 | AF15: 0 | AG15: 0 | AH15: 0 | AI15: 0 | AJ15: 0 | AK15: 0 | AL15: 0 | AM15: 0 | BZ15: =R15 -> Petrol | CA15: =S15 -> 0 | CB15: =T15 -> 0 | CC15: =U15 -> 0 | CD15: =V15 -> 0 | CE15: =W15 -> 0 | CF15: =X15 -> 0 | CG15: =Y15 -> 0 | ... CI15: =AA15 -> 0 | CL15: =AD15 -> Petrol | CM15: =AE15 -> 0 | CN15: =AF15 -> 0 | CO15: =AG15 -> 0 | CP15: =AH15 -> 0 | CQ15: =AI15 -> 0 | CR15: =AJ15 -> 0 | CS15: =AK15 -> 0 | ... CU15: =AM15 -> 0 | DO15: Petrol | DP15: 0 | DQ15: 0 | DR15: 0 | DS15: 0 | DT15: 0 | DU15: 0 | DV15: 0 | DW15: 0 | DX15: 0 | EA15: Petrol | EB15: 0 | EC15: 0 | ED15: 0 | EE15: 0 | EF15: 0 | EG15: 0 | EH15: 0 | EI15: =DW15/DW51 -> 0 | EJ15: 0 | FW15: =DO15 -> Petrol | FX15: =DP15 -> 0 | FY15: =DQ15 -> 0 | FZ15: =DR15 -> 0 | GA15: =DS15 -> 0 | GB15: =DT15 -> 0 | GC15: =DU15 -> 0 | GD15: =DV15 -> 0 | ... GF15: =DX15 -> 0 | GI15: =EA15 -> Petrol | GJ15: =EB15 -> 0 | GK15: =EC15 -> 0 | GL15: =ED15 -> 0 | GM15: =EE15 -> 0 | GN15: =EF15 -> 0 | GO15: =EG15 -> 0 | GP15: =EH15 -> 0 | ... GR15: =EJ15 -> 0 | HL15: Petrol | HM15: =FX15-X_Final_2000!S14 -> 0 | HN15: =FY15-X_Final_2000!T14 -> 0 | HO15: =FZ15-X_Final_2000!U14 -> 0 | HP15: =GA15-X_Final_2000!V14 -> 0 | HQ15: =GB15-X_Final_2000!W14 -> 0 | HR15: =GC15-X_Final_2000!X14 -> 0 | HS15: =GD15-X_Final_2000!Y14 -> 0 | HT15: =GE15-X_Final_2000!Z14 -> 0 | HU15: =GF15-X_Final_2000!AA14 -> 0 | HX15: Petrol | HY15: =GJ15-X_Final_2000!AE14 -> 0 | HZ15: =GK15-X_Final_2000!AF14 -> 0 | IA15: =GL15-X_Final_2000!AG14 -> 0 | IB15: =GM15-X_Final_2000!AH14 -> 0 | IC15: =GN15-X_Final_2000!AI14 -> 0 | ID15: =GO15-X_Final_2000!AJ14 -> 0 | IE15: =GP15-X_Final_2000!AK14 -> 0 | IF15: =GQ15-X_Final_2000!AL14 -> 0 | IG15: =GR15-X_Final_2000!AM14 -> 0
A16: Petrol [from Dist.] | B16: 1 | R16: Petrol [from Dist.] | S16: 0 | T16: 0 | U16: 0 | V16: 0 | W16: 0 | X16: 0 | Y16: 0 | Z16: 500 | AA16: 0 | AD16: Petrol [from Dist.] | AE16: 0 | AF16: 0 | AG16: 0 | AH16: 0 | AI16: 0 | AJ16: 0 | AK16: 0 | AL16: 1 | AM16: 0 | BZ16: =R16 -> Petrol [from Dist.] | CA16: =S16 -> 0 | CB16: =T16 -> 0 | CC16: =U16 -> 0 | CD16: =V16 -> 0 | CE16: =W16 -> 0 | CF16: =X16 -> 0 | CG16: =Y16 -> 0 | ... CI16: =AA16 -> 0 | CL16: =AD16 -> Petrol [from Dist.] | CM16: =AE16 -> 0 | CN16: =AF16 -> 0 | CO16: =AG16 -> 0 | CP16: =AH16 -> 0 | CQ16: =AI16 -> 0 | CR16: =AJ16 -> 0 | CS16: =AK16 -> 0 | ... CU16: =AM16 -> 0 | DO16: Petrol [from Dist.] | DP16: 0 | DQ16: 0 | DR16: 0 | DS16: 0 | DT16: 0 | DU16: 0 | DV16: 0 | DW16: =DW52 -> 530 | DX16: 0 | EA16: Petrol [from Dist.] | EB16: 0 | EC16: 0 | ED16: 0 | EE16: 0 | EF16: 0 | EG16: 0 | EH16: 0 | EI16: =DW16/DW52 -> 1 | EJ16: 0 | FW16: =DO16 -> Petrol [from Dist.] | FX16: =DP16 -> 0 | FY16: =DQ16 -> 0 | FZ16: =DR16 -> 0 | GA16: =DS16 -> 0 | GB16: =DT16 -> 0 | GC16: =DU16 -> 0 | GD16: =DV16 -> 0 | ... GF16: =DX16 -> 0 | GI16: =EA16 -> Petrol [from Dist.] | GJ16: =EB16 -> 0 | GK16: =EC16 -> 0 | GL16: =ED16 -> 0 | GM16: =EE16 -> 0 | GN16: =EF16 -> 0 | GO16: =EG16 -> 0 | GP16: =EH16 -> 0 | ... GR16: =EJ16 -> 0 | HL16: Petrol [from Dist.] | HM16: =FX16-X_Final_2000!S15 -> 0 | HN16: =FY16-X_Final_2000!T15 -> 0 | HO16: =FZ16-X_Final_2000!U15 -> 0 | HP16: =GA16-X_Final_2000!V15 -> 0 | HQ16: =GB16-X_Final_2000!W15 -> 0 | HR16: =GC16-X_Final_2000!X15 -> 0 | HS16: =GD16-X_Final_2000!Y15 -> 0 | HT16: =GE16-X_Final_2000!Z15 -> 0 | HU16: =GF16-X_Final_2000!AA15 -> 0 | HX16: Petrol [from Dist.] | HY16: =GJ16-X_Final_2000!AE15 -> 0 | HZ16: =GK16-X_Final_2000!AF15 -> 0 | IA16: =GL16-X_Final_2000!AG15 -> 0 | IB16: =GM16-X_Final_2000!AH15 -> 0 | IC16: =GN16-X_Final_2000!AI15 -> 0 | ID16: =GO16-X_Final_2000!AJ15 -> 0 | IE16: =GP16-X_Final_2000!AK15 -> 0 | IF16: =GQ16-X_Final_2000!AL15 -> 0 | IG16: =GR16-X_Final_2000!AM15 -> 0
B17: S_units | S17: U_EIOU | AE17: r_EIOU | CA17: U_EIOU | CM17: r_EIOU | DP17: U_EIOU | EB17: r_EIOU | FX17: =DP17 -> U_EIOU | GJ17: =EB17 -> r_EIOU | HM17: U_EROI_Excel – U_EROI_Recca | HY17: r_EROI_Excel – r_EROI_Recca
CA18: Unchanged | CM18: Unchanged | DP18: Now in exergy terms | EB18: Now for exergy (unchanged) | FX18: Unchanged | GJ18: Unchanged
S20: Crude dist. | T20: Diesel dist. | U20: Elect. grid | V20: Gas wells & proc. | W20: NG dist. | X20: Oil fields | Y20: Oil refineries | Z20: Petrol dist. | AA20: Power plants | CA20: Crude dist. | CB20: Diesel dist. | CC20: Elect. grid | CD20: Gas wells & proc. | CE20: NG dist. | CF20: Oil fields | CG20: Oil refineries | CH20: Petrol dist. | CI20: Power plants | DP20: Crude dist. | DQ20: Diesel dist. | DR20: Elect. grid | DS20: Gas wells & proc. | DT20: NG dist. | DU20: Oil fields | DV20: Oil refineries | DW20: Petrol dist. | DX20: Power plants | FW20: =DO20 -> 0 | FX20: =DP20 -> Crude dist. | FY20: =DQ20 -> Diesel dist. | FZ20: =DR20 -> Elect. grid | GA20: =DS20 -> Gas wells & proc. | GB20: =DT20 -> NG dist. | GC20: =DU20 -> Oil fields | GD20: =DV20 -> Oil refineries | ... GF20: =DX20 -> Power plants | HM20: Crude dist. | HN20: Diesel dist. | HO20: Elect. grid | HP20: Gas wells & proc. | HQ20: NG dist. | HR20: Oil fields | HS20: Oil refineries | HT20: Petrol dist. | HU20: Power plants
A21: This tab starts with the E_Final_2000 information and calculates losses, exergy, and exergy destruction. | R21: Crude | S21: 0 | T21: 0 | U21: 0 | V21: 0 | W21: 0 | X21: 50000 | Y21: 0 | Z21: 0 | AA21: 0 | BZ21: Crude | CA21: =S21 -> 0 | CB21: =T21 -> 0 | CC21: =U21 -> 0 | CD21: =V21 -> 0 | CE21: =W21 -> 0 | CF21: =X21 -> 50000 | CG21: =Y21 -> 0 | CH21: =Z21 -> 0 | CI21: =AA21 -> 0 | DO21: Crude | DP21: =DP39-DP3 -> 0 | DQ21: =DQ39-DQ3 -> 0 | DR21: =DR39-DR3 -> 0 | DS21: =DS39-DS3 -> 0 | DT21: =DT39-DT3 -> 0 | DU21: =DU39-DU3 -> 53000 | DV21: =DV39-DV3 -> 0 | DW21: =DW39-DW3 -> 0 | DX21: =DX39-DX3 -> 0 | FW21: =DO21 -> Crude | FX21: =DP21 -> 0 | FY21: =DQ21 -> 0 | FZ21: =DR21 -> 0 | GA21: =DS21 -> 0 | GB21: =DT21 -> 0 | GC21: =DU21 -> 53000 | GD21: =DV21 -> 0 | ... GF21: =DX21 -> 0 | HL21: Crude | HM21: =FX21-X_Final_2000!S20 -> 0 | HN21: =FY21-X_Final_2000!T20 -> 0 | HO21: =FZ21-X_Final_2000!U20 -> 0 | HP21: =GA21-X_Final_2000!V20 -> 0 | HQ21: =GB21-X_Final_2000!W20 -> 0 | HR21: =GC21-X_Final_2000!X20 -> 0 | HS21: =GD21-X_Final_2000!Y20 -> 0 | HT21: =GE21-X_Final_2000!Z20 -> 0 | HU21: =GF21-X_Final_2000!AA20 -> 0
A22: Then compares to results from Recca in X_Final_2000. | R22: Crude [from Dist.] | S22: 0 | T22: 0 | U22: 0 | V22: 0 | W22: 0 | X22: 0 | Y22: 47000 | Z22: 0 | AA22: 0 | BZ22: Crude [from Dist.] | CA22: =S22 -> 0 | CB22: =T22 -> 0 | CC22: =U22 -> 0 | CD22: =V22 -> 0 | CE22: =W22 -> 0 | CF22: =X22 -> 0 | CG22: =Y22 -> 47000 | CH22: =Z22 -> 0 | CI22: =AA22 -> 0 | DO22: Crude [from Dist.] | DP22: =DP40-DP4 -> 0 | DQ22: =DQ40-DQ4 -> 0 | DR22: =DR40-DR4 -> 0 | DS22: =DS40-DS4 -> 0 | DT22: =DT40-DT4 -> 0 | DU22: =DU40-DU4 -> 0 | DV22: =DV40-DV4 -> 49820 | DW22: =DW40-DW4 -> 0 | DX22: =DX40-DX4 -> 0 | FW22: =DO22 -> Crude [from Dist.] | FX22: =DP22 -> 0 | FY22: =DQ22 -> 0 | FZ22: =DR22 -> 0 | GA22: =DS22 -> 0 | GB22: =DT22 -> 0 | GC22: =DU22 -> 0 | GD22: =DV22 -> 49820 | ... GF22: =DX22 -> 0 | HL22: Crude [from Dist.] | HM22: =FX22-X_Final_2000!S21 -> 0 | HN22: =FY22-X_Final_2000!T21 -> 0 | HO22: =FZ22-X_Final_2000!U21 -> 0 | HP22: =GA22-X_Final_2000!V21 -> 0 | HQ22: =GB22-X_Final_2000!W21 -> 0 | HR22: =GC22-X_Final_2000!X21 -> 0 | HS22: =GD22-X_Final_2000!Y21 -> 0 | HT22: =GE22-X_Final_2000!Z21 -> 0 | HU22: =GF22-X_Final_2000!AA21 -> 0
R23: Crude [from Fields] | S23: 47500 | T23: 0 | U23: 0 | V23: 0 | W23: 0 | X23: 0 | Y23: 0 | Z23: 0 | AA23: 0 | BZ23: Crude [from Fields] | CA23: =S23 -> 47500 | CB23: =T23 -> 0 | CC23: =U23 -> 0 | CD23: =V23 -> 0 | CE23: =W23 -> 0 | CF23: =X23 -> 0 | CG23: =Y23 -> 0 | CH23: =Z23 -> 0 | CI23: =AA23 -> 0 | DO23: Crude [from Fields] | DP23: =DP41-DP5 -> 50350 | DQ23: =DQ41-DQ5 -> 0 | DR23: =DR41-DR5 -> 0 | DS23: =DS41-DS5 -> 0 | DT23: =DT41-DT5 -> 0 | DU23: =DU41-DU5 -> 0 | DV23: =DV41-DV5 -> 0 | DW23: =DW41-DW5 -> 0 | DX23: =DX41-DX5 -> 0 | FW23: =DO23 -> Crude [from Fields] | FX23: =DP23 -> 50350 | FY23: =DQ23 -> 0 | FZ23: =DR23 -> 0 | GA23: =DS23 -> 0 | GB23: =DT23 -> 0 | GC23: =DU23 -> 0 | GD23: =DV23 -> 0 | ... GF23: =DX23 -> 0 | HL23: Crude [from Fields] | HM23: =FX23-X_Final_2000!S22 -> 0 | HN23: =FY23-X_Final_2000!T22 -> 0 | HO23: =FZ23-X_Final_2000!U22 -> 0 | HP23: =GA23-X_Final_2000!V22 -> 0 | HQ23: =GB23-X_Final_2000!W22 -> 0 | HR23: =GC23-X_Final_2000!X22 -> 0 | HS23: =GD23-X_Final_2000!Y22 -> 0 | HT23: =GE23-X_Final_2000!Z22 -> 0 | HU23: =GF23-X_Final_2000!AA22 -> 0
R24: Destroyed exergy | S24: 0 | T24: 0 | U24: 0 | V24: 0 | W24: 0 | X24: 0 | Y24: 0 | Z24: 0 | AA24: 0 | BZ24: Destroyed exergy | CA24: =S24 -> 0 | CB24: =T24 -> 0 | CC24: =U24 -> 0 | CD24: =V24 -> 0 | CE24: =W24 -> 0 | CF24: =X24 -> 0 | CG24: =Y24 -> 0 | CH24: =Z24 -> 0 | CI24: =AA24 -> 0 | DO24: Destroyed exergy | DP24: =DP42-DP6 -> 0 | DQ24: =DQ42-DQ6 -> 0 | DR24: =DR42-DR6 -> 0 | DS24: =DS42-DS6 -> 0 | DT24: =DT42-DT6 -> 0 | DU24: =DU42-DU6 -> 0 | DV24: =DV42-DV6 -> 0 | DW24: =DW42-DW6 -> 0 | DX24: =DX42-DX6 -> 0 | FW24: =DO24 -> Destroyed exergy | FX24: =DP24 -> 0 | FY24: =DQ24 -> 0 | FZ24: =DR24 -> 0 | GA24: =DS24 -> 0 | GB24: =DT24 -> 0 | GC24: =DU24 -> 0 | GD24: =DV24 -> 0 | ... GF24: =DX24 -> 0 | HL24: Destroyed exergy | HM24: =FX24-X_Final_2000!S23 -> 0 | HN24: =FY24-X_Final_2000!T23 -> 0 | HO24: =FZ24-X_Final_2000!U23 -> 0 | HP24: =GA24-X_Final_2000!V23 -> 0 | HQ24: =GB24-X_Final_2000!W23 -> 0 | HR24: =GC24-X_Final_2000!X23 -> 0 | HS24: =GD24-X_Final_2000!Y23 -> 0 | HT24: =GE24-X_Final_2000!Z23 -> 0 | HU24: =GF24-X_Final_2000!AA23 -> 0
R25: Diesel | S25: 0 | T25: 15500 | U25: 0 | V25: 0 | W25: 0 | X25: 0 | Y25: 0 | Z25: 0 | AA25: 0 | BZ25: Diesel | CA25: =S25 -> 0 | CB25: =T25 -> 15500 | CC25: =U25 -> 0 | CD25: =V25 -> 0 | CE25: =W25 -> 0 | CF25: =X25 -> 0 | CG25: =Y25 -> 0 | CH25: =Z25 -> 0 | CI25: =AA25 -> 0 | DO25: Diesel | DP25: =DP43-DP7 -> 0 | DQ25: =DQ43-DQ7 -> 16430 | DR25: =DR43-DR7 -> 0 | DS25: =DS43-DS7 -> 0 | DT25: =DT43-DT7 -> 0 | DU25: =DU43-DU7 -> 0 | DV25: =DV43-DV7 -> 0 | DW25: =DW43-DW7 -> 0 | DX25: =DX43-DX7 -> 0 | FW25: =DO25 -> Diesel | FX25: =DP25 -> 0 | FY25: =DQ25 -> 16430 | FZ25: =DR25 -> 0 | GA25: =DS25 -> 0 | GB25: =DT25 -> 0 | GC25: =DU25 -> 0 | GD25: =DV25 -> 0 | ... GF25: =DX25 -> 0 | HL25: Diesel | HM25: =FX25-X_Final_2000!S24 -> 0 | HN25: =FY25-X_Final_2000!T24 -> 0 | HO25: =FZ25-X_Final_2000!U24 -> 0 | HP25: =GA25-X_Final_2000!V24 -> 0 | HQ25: =GB25-X_Final_2000!W24 -> 0 | HR25: =GC25-X_Final_2000!X24 -> 0 | HS25: =GD25-X_Final_2000!Y24 -> 0 | HT25: =GE25-X_Final_2000!Z24 -> 0 | HU25: =GF25-X_Final_2000!AA24 -> 0
R26: Diesel [from Dist.] | S26: 0 | T26: 0 | U26: 0 | V26: 0 | W26: 0 | X26: 0 | Y26: 0 | Z26: 0 | AA26: 0 | BZ26: Diesel [from Dist.] | CA26: =S26 -> 0 | CB26: =T26 -> 0 | CC26: =U26 -> 0 | CD26: =V26 -> 0 | CE26: =W26 -> 0 | CF26: =X26 -> 0 | CG26: =Y26 -> 0 | CH26: =Z26 -> 0 | CI26: =AA26 -> 0 | DO26: Diesel [from Dist.] | DP26: =DP44-DP8 -> 0 | DQ26: =DQ44-DQ8 -> 0 | DR26: =DR44-DR8 -> 0 | DS26: =DS44-DS8 -> 0 | DT26: =DT44-DT8 -> 0 | DU26: =DU44-DU8 -> 0 | DV26: =DV44-DV8 -> 0 | DW26: =DW44-DW8 -> 0 | DX26: =DX44-DX8 -> 0 | FW26: =DO26 -> Diesel [from Dist.] | FX26: =DP26 -> 0 | FY26: =DQ26 -> 0 | FZ26: =DR26 -> 0 | GA26: =DS26 -> 0 | GB26: =DT26 -> 0 | GC26: =DU26 -> 0 | GD26: =DV26 -> 0 | ... GF26: =DX26 -> 0 | HL26: Diesel [from Dist.] | HM26: =FX26-X_Final_2000!S25 -> 0 | HN26: =FY26-X_Final_2000!T25 -> 0 | HO26: =FZ26-X_Final_2000!U25 -> 0 | HP26: =GA26-X_Final_2000!V25 -> 0 | HQ26: =GB26-X_Final_2000!W25 -> 0 | HR26: =GC26-X_Final_2000!X25 -> 0 | HS26: =GD26-X_Final_2000!Y25 -> 0 | HT26: =GE26-X_Final_2000!Z25 -> 0 | HU26: =GF26-X_Final_2000!AA25 -> 0
R27: Elect | S27: 0 | T27: 0 | U27: 6400 | V27: 0 | W27: 0 | X27: 0 | Y27: 0 | Z27: 0 | AA27: 0 | BZ27: Elect | CA27: =S27 -> 0 | CB27: =T27 -> 0 | CC27: =U27 -> 6400 | CD27: =V27 -> 0 | CE27: =W27 -> 0 | CF27: =X27 -> 0 | CG27: =Y27 -> 0 | CH27: =Z27 -> 0 | CI27: =AA27 -> 0 | DO27: Elect | DP27: =DP45-DP9 -> 0 | DQ27: =DQ45-DQ9 -> 0 | DR27: =DR45-DR9 -> 6400 | DS27: =DS45-DS9 -> 0 | DT27: =DT45-DT9 -> 0 | DU27: =DU45-DU9 -> 0 | DV27: =DV45-DV9 -> 0 | DW27: =DW45-DW9 -> 0 | DX27: =DX45-DX9 -> 0 | FW27: =DO27 -> Elect | FX27: =DP27 -> 0 | FY27: =DQ27 -> 0 | FZ27: =DR27 -> 6400 | GA27: =DS27 -> 0 | GB27: =DT27 -> 0 | GC27: =DU27 -> 0 | GD27: =DV27 -> 0 | ... GF27: =DX27 -> 0 | HL27: Elect | HM27: =FX27-X_Final_2000!S26 -> 0 | HN27: =FY27-X_Final_2000!T26 -> 0 | HO27: =FZ27-X_Final_2000!U26 -> 0 | HP27: =GA27-X_Final_2000!V26 -> 0 | HQ27: =GB27-X_Final_2000!W26 -> 0 | HR27: =GC27-X_Final_2000!X26 -> 0 | HS27: =GD27-X_Final_2000!Y26 -> 0 | HT27: =GE27-X_Final_2000!Z26 -> 0 | HU27: =GF27-X_Final_2000!AA26 -> 0
R28: Elect [from Grid] | S28: 0 | T28: 0 | U28: 0 | V28: 0 | W28: 0 | X28: 0 | Y28: 0 | Z28: 0 | AA28: 0 | BZ28: Elect [from Grid] | CA28: =S28 -> 0 | CB28: =T28 -> 0 | CC28: =U28 -> 0 | CD28: =V28 -> 0 | CE28: =W28 -> 0 | CF28: =X28 -> 0 | CG28: =Y28 -> 0 | CH28: =Z28 -> 0 | CI28: =AA28 -> 0 | DO28: Elect [from Grid] | DP28: =DP46-DP10 -> 0 | DQ28: =DQ46-DQ10 -> 0 | DR28: =DR46-DR10 -> 0 | DS28: =DS46-DS10 -> 0 | DT28: =DT46-DT10 -> 0 | DU28: =DU46-DU10 -> 0 | DV28: =DV46-DV10 -> 0 | DW28: =DW46-DW10 -> 0 | DX28: =DX46-DX10 -> 0 | FW28: =DO28 -> Elect [from Grid] | FX28: =DP28 -> 0 | FY28: =DQ28 -> 0 | FZ28: =DR28 -> 0 | GA28: =DS28 -> 0 | GB28: =DT28 -> 0 | GC28: =DU28 -> 0 | GD28: =DV28 -> 0 | ... GF28: =DX28 -> 0 | HL28: Elect [from Grid] | HM28: =FX28-X_Final_2000!S27 -> 0 | HN28: =FY28-X_Final_2000!T27 -> 0 | HO28: =FZ28-X_Final_2000!U27 -> 0 | HP28: =GA28-X_Final_2000!V27 -> 0 | HQ28: =GB28-X_Final_2000!W27 -> 0 | HR28: =GC28-X_Final_2000!X27 -> 0 | HS28: =GD28-X_Final_2000!Y27 -> 0 | HT28: =GE28-X_Final_2000!Z27 -> 0 | HU28: =GF28-X_Final_2000!AA27 -> 0
R29: MTH.200.C -> Transformation losses | S29: 0 | T29: 0 | U29: 0 | V29: 0 | W29: 0 | X29: 0 | Y29: 0 | Z29: 0 | AA29: 0 | BZ29: MTH.200.C -> Transformation losses | CA29: =S29 -> 0 | CB29: =T29 -> 0 | CC29: =U29 -> 0 | CD29: =V29 -> 0 | CE29: =W29 -> 0 | CF29: =X29 -> 0 | CG29: =Y29 -> 0 | CH29: =Z29 -> 0 | CI29: =AA29 -> 0 | DO29: MTH.200.C -> Transformation losses | DP29: =DP47-DP11 -> 0 | DQ29: =DQ47-DQ11 -> 0 | DR29: =DR47-DR11 -> 0 | DS29: =DS47-DS11 -> 0 | DT29: =DT47-DT11 -> 0 | DU29: =DU47-DU11 -> 0 | DV29: =DV47-DV11 -> 0 | DW29: =DW47-DW11 -> 0 | DX29: =DX47-DX11 -> 0 | FW29: =DO29 -> MTH.200.C -> Transformation losses | FX29: =DP29 -> 0 | FY29: =DQ29 -> 0 | FZ29: =DR29 -> 0 | GA29: =DS29 -> 0 | GB29: =DT29 -> 0 | GC29: =DU29 -> 0 | GD29: =DV29 -> 0 | ... GF29: =DX29 -> 0 | HL29: MTH.200.C -> Transformation losses | HM29: =FX29-X_Final_2000!S28 -> 0 | HN29: =FY29-X_Final_2000!T28 -> 0 | HO29: =FZ29-X_Final_2000!U28 -> 0 | HP29: =GA29-X_Final_2000!V28 -> 0 | HQ29: =GB29-X_Final_2000!W28 -> 0 | HR29: =GC29-X_Final_2000!X28 -> 0 | HS29: =GD29-X_Final_2000!Y28 -> 0 | HT29: =GE29-X_Final_2000!Z28 -> 0 | HU29: =GF29-X_Final_2000!AA28 -> 0
R30: NG | S30: 0 | T30: 0 | U30: 0 | V30: 43000 | W30: 0 | X30: 0 | Y30: 0 | Z30: 0 | AA30: 0 | BZ30: NG | CA30: =S30 -> 0 | CB30: =T30 -> 0 | CC30: =U30 -> 0 | CD30: =V30 -> 43000 | CE30: =W30 -> 0 | CF30: =X30 -> 0 | CG30: =Y30 -> 0 | CH30: =Z30 -> 0 | CI30: =AA30 -> 0 | DO30: NG | DP30: =DP48-DP12 -> 0 | DQ30: =DQ48-DQ12 -> 0 | DR30: =DR48-DR12 -> 0 | DS30: =DS48-DS12 -> 44720 | DT30: =DT48-DT12 -> 0 | DU30: =DU48-DU12 -> 0 | DV30: =DV48-DV12 -> 0 | DW30: =DW48-DW12 -> 0 | DX30: =DX48-DX12 -> 0 | FW30: =DO30 -> NG | FX30: =DP30 -> 0 | FY30: =DQ30 -> 0 | FZ30: =DR30 -> 0 | GA30: =DS30 -> 44720 | GB30: =DT30 -> 0 | GC30: =DU30 -> 0 | GD30: =DV30 -> 0 | ... GF30: =DX30 -> 0 | HL30: NG | HM30: =FX30-X_Final_2000!S29 -> 0 | HN30: =FY30-X_Final_2000!T29 -> 0 | HO30: =FZ30-X_Final_2000!U29 -> 0 | HP30: =GA30-X_Final_2000!V29 -> 0 | HQ30: =GB30-X_Final_2000!W29 -> 0 | HR30: =GC30-X_Final_2000!X29 -> 0 | HS30: =GD30-X_Final_2000!Y29 -> 0 | HT30: =GE30-X_Final_2000!Z29 -> 0 | HU30: =GF30-X_Final_2000!AA29 -> 0
R31: NG [from Dist.] | S31: 0 | T31: 0 | U31: 0 | V31: 0 | W31: 0 | X31: 0 | Y31: 0 | Z31: 0 | AA31: 16000 | BZ31: NG [from Dist.] | CA31: =S31 -> 0 | CB31: =T31 -> 0 | CC31: =U31 -> 0 | CD31: =V31 -> 0 | CE31: =W31 -> 0 | CF31: =X31 -> 0 | CG31: =Y31 -> 0 | CH31: =Z31 -> 0 | CI31: =AA31 -> 16000 | DO31: NG [from Dist.] | DP31: =DP49-DP13 -> 0 | DQ31: =DQ49-DQ13 -> 0 | DR31: =DR49-DR13 -> 0 | DS31: =DS49-DS13 -> 0 | DT31: =DT49-DT13 -> 0 | DU31: =DU49-DU13 -> 0 | DV31: =DV49-DV13 -> 0 | DW31: =DW49-DW13 -> 0 | DX31: =DX49-DX13 -> 16640 | FW31: =DO31 -> NG [from Dist.] | FX31: =DP31 -> 0 | FY31: =DQ31 -> 0 | FZ31: =DR31 -> 0 | GA31: =DS31 -> 0 | GB31: =DT31 -> 0 | GC31: =DU31 -> 0 | GD31: =DV31 -> 0 | ... GF31: =DX31 -> 16640 | HL31: NG [from Dist.] | HM31: =FX31-X_Final_2000!S30 -> 0 | HN31: =FY31-X_Final_2000!T30 -> 0 | HO31: =FZ31-X_Final_2000!U30 -> 0 | HP31: =GA31-X_Final_2000!V30 -> 0 | HQ31: =GB31-X_Final_2000!W30 -> 0 | HR31: =GC31-X_Final_2000!X30 -> 0 | HS31: =GD31-X_Final_2000!Y30 -> 0 | HT31: =GE31-X_Final_2000!Z30 -> 0 | HU31: =GF31-X_Final_2000!AA30 -> 0
R32: NG [from Wells] | S32: 0 | T32: 0 | U32: 0 | V32: 0 | W32: 41000 | X32: 0 | Y32: 0 | Z32: 0 | AA32: 0 | BZ32: NG [from Wells] | CA32: =S32 -> 0 | CB32: =T32 -> 0 | CC32: =U32 -> 0 | CD32: =V32 -> 0 | CE32: =W32 -> 41000 | CF32: =X32 -> 0 | CG32: =Y32 -> 0 | CH32: =Z32 -> 0 | CI32: =AA32 -> 0 | DO32: NG [from Wells] | DP32: =DP50-DP14 -> 0 | DQ32: =DQ50-DQ14 -> 0 | DR32: =DR50-DR14 -> 0 | DS32: =DS50-DS14 -> 0 | DT32: =DT50-DT14 -> 42640 | DU32: =DU50-DU14 -> 0 | DV32: =DV50-DV14 -> 0 | DW32: =DW50-DW14 -> 0 | DX32: =DX50-DX14 -> 0 | FW32: =DO32 -> NG [from Wells] | FX32: =DP32 -> 0 | FY32: =DQ32 -> 0 | FZ32: =DR32 -> 0 | GA32: =DS32 -> 0 | GB32: =DT32 -> 42640 | GC32: =DU32 -> 0 | GD32: =DV32 -> 0 | ... GF32: =DX32 -> 0 | HL32: NG [from Wells] | HM32: =FX32-X_Final_2000!S31 -> 0 | HN32: =FY32-X_Final_2000!T31 -> 0 | HO32: =FZ32-X_Final_2000!U31 -> 0 | HP32: =GA32-X_Final_2000!V31 -> 0 | HQ32: =GB32-X_Final_2000!W31 -> 0 | HR32: =GC32-X_Final_2000!X31 -> 0 | HS32: =GD32-X_Final_2000!Y31 -> 0 | HT32: =GE32-X_Final_2000!Z31 -> 0 | HU32: =GF32-X_Final_2000!AA31 -> 0
R33: Petrol | S33: 0 | T33: 0 | U33: 0 | V33: 0 | W33: 0 | X33: 0 | Y33: 0 | Z33: 26500 | AA33: 0 | BZ33: Petrol | CA33: =S33 -> 0 | CB33: =T33 -> 0 | CC33: =U33 -> 0 | CD33: =V33 -> 0 | CE33: =W33 -> 0 | CF33: =X33 -> 0 | CG33: =Y33 -> 0 | CH33: =Z33 -> 26500 | CI33: =AA33 -> 0 | DO33: Petrol | DP33: =DP51-DP15 -> 0 | DQ33: =DQ51-DQ15 -> 0 | DR33: =DR51-DR15 -> 0 | DS33: =DS51-DS15 -> 0 | DT33: =DT51-DT15 -> 0 | DU33: =DU51-DU15 -> 0 | DV33: =DV51-DV15 -> 0 | DW33: =DW51-DW15 -> 28090 | DX33: =DX51-DX15 -> 0 | FW33: =DO33 -> Petrol | FX33: =DP33 -> 0 | FY33: =DQ33 -> 0 | FZ33: =DR33 -> 0 | GA33: =DS33 -> 0 | GB33: =DT33 -> 0 | GC33: =DU33 -> 0 | GD33: =DV33 -> 0 | ... GF33: =DX33 -> 0 | HL33: Petrol | HM33: =FX33-X_Final_2000!S32 -> 0 | HN33: =FY33-X_Final_2000!T32 -> 0 | HO33: =FZ33-X_Final_2000!U32 -> 0 | HP33: =GA33-X_Final_2000!V32 -> 0 | HQ33: =GB33-X_Final_2000!W32 -> 0 | HR33: =GC33-X_Final_2000!X32 -> 0 | HS33: =GD33-X_Final_2000!Y32 -> 0 | HT33: =GE33-X_Final_2000!Z32 -> 0 | HU33: =GF33-X_Final_2000!AA32 -> 0
R34: Petrol [from Dist.] | S34: 0 | T34: 0 | U34: 0 | V34: 0 | W34: 0 | X34: 0 | Y34: 0 | Z34: 0 | AA34: 0 | BZ34: Petrol [from Dist.] | CA34: =S34 -> 0 | CB34: =T34 -> 0 | CC34: =U34 -> 0 | CD34: =V34 -> 0 | CE34: =W34 -> 0 | CF34: =X34 -> 0 | CG34: =Y34 -> 0 | CH34: =Z34 -> 0 | CI34: =AA34 -> 0 | DO34: Petrol [from Dist.] | DP34: =DP52-DP16 -> 0 | DQ34: =DQ52-DQ16 -> 0 | DR34: =DR52-DR16 -> 0 | DS34: =DS52-DS16 -> 0 | DT34: =DT52-DT16 -> 0 | DU34: =DU52-DU16 -> 0 | DV34: =DV52-DV16 -> 0 | DW34: =DW52-DW16 -> 0 | DX34: =DX52-DX16 -> 0 | FW34: =DO34 -> Petrol [from Dist.] | FX34: =DP34 -> 0 | FY34: =DQ34 -> 0 | FZ34: =DR34 -> 0 | GA34: =DS34 -> 0 | GB34: =DT34 -> 0 | GC34: =DU34 -> 0 | GD34: =DV34 -> 0 | ... GF34: =DX34 -> 0 | HL34: Petrol [from Dist.] | HM34: =FX34-X_Final_2000!S33 -> 0 | HN34: =FY34-X_Final_2000!T33 -> 0 | HO34: =FZ34-X_Final_2000!U33 -> 0 | HP34: =GA34-X_Final_2000!V33 -> 0 | HQ34: =GB34-X_Final_2000!W33 -> 0 | HR34: =GC34-X_Final_2000!X33 -> 0 | HS34: =GD34-X_Final_2000!Y33 -> 0 | HT34: =GE34-X_Final_2000!Z33 -> 0 | HU34: =GF34-X_Final_2000!AA33 -> 0
S35: U_feed | CA35: U_feed | DP35: U_feed | FX35: =DP35 -> U_feed | HM35: U_feed_Excel – U_feed_Recca
CA36: Unchanged | DP36: Now in exergy terms | FX36: Unchanged
